Workbook

Sheet Start Here
A1: Debt Payoff Planner — Snowball & Avalanche
A2: Simple Sheets Co. — Excel + Google Sheets
A4: Setup
A5: 1. List every debt with balance, APR and minimum payment. Enter how much extra you can pay each month.
A6: 2. Choose Snowball (smallest balance first) or Avalanche (highest rate first). The plan shows payoff order, months to debt-free, and total interest paid.
A7: 3. The Schedule tab simulates month by month (up to 120 months).
A9: Conventions
A10: • Yellow cells with blue text are inputs. Type over the sample numbers.
A11: • Black text is a formula. Leave it alone unless you know what you're changing.
A12: • Green text pulls from another tab.
A13: • Works in Excel 2016+ and Google Sheets (File > Import > Upload > Replace). No macros.
A14: • Simulation applies extra payment to the target debt, then rolls each paid-off minimum into the next one.
A16: For planning and educational use only. Not financial, legal, or tax advice. Every number is an estimate you should verify for your own business.

Sheet Dashboard
B2: Debt-Free Dashboard
B3: Your payoff plan, month by month.
B5: TOTAL DEBT TODAY | E5: PAYING PER MONTH | H5: MONTHS TO DEBT-FREE | K5: TOTAL INTEREST YOU'LL PAY
B6: =Debts!B16 -> 39800 | E6: =Debts!B17 -> 1200 | H6: =Debts!B18 -> 39 | K6: =Debts!B19 -> 5112.0052
B9: DEBT-FREE DATE | E9: EXTRA PAYMENT / MONTH | H9: AVERAGE APR
B10: =IF(ISNUMBER(Debts!B18),TEXT(EDATE(TODAY(),Debts!B18),"mmm yyyy"),"—") -> Dec 2029 | E10: =Debts!B4 -> 400 | H10: =IF(Debts!B16=0,0,SUMPRODUCT(Debts!B8:B15,Debts!C8:C15)/Debts!B16) -> 0.098017588

Sheet Debts
A1: Debts
A3: How to use: type your numbers in the yellow cells (blue text). Everything else calculates.
A4: Extra payment per month (beyond minimums) | B4: 400
A5: Method (Snowball or Avalanche) | B5: Avalanche
A7: Debt | B7: Balance | C7: APR | D7: Minimum payment | E7: Payoff order | F7: Months to payoff (alone)
A8: Credit card A | B8: 6200 | C8: 0.249 | D8: 155 | E8: =IF(A8="","",IF($B$5="Snowball",RANK(B8,$B$8:$B$15,1),RANK(C8,$C$8:$C$15,0))) -> 1 | F8: =IF(OR(A8="",D8=0),"",IF(C8=0,ROUNDUP(B8/D8,0),IF(D8<=B8*C8/12,"min too low",ROUNDUP(-LOG(1-B8*C8/12/D8)/LOG(1+C8/12),0)))) -> 87
A9: Credit card B | B9: 2400 | C9: 0.219 | D9: 75 | E9: =IF(A9="","",IF($B$5="Snowball",RANK(B9,$B$8:$B$15,1),RANK(C9,$C$8:$C$15,0))) -> 2 | F9: =IF(OR(A9="",D9=0),"",IF(C9=0,ROUNDUP(B9/D9,0),IF(D9<=B9*C9/12,"min too low",ROUNDUP(-LOG(1-B9*C9/12/D9)/LOG(1+C9/12),0)))) -> 49
A10: Car loan | B10: 11800 | C10: 0.069 | D10: 310 | E10: =IF(A10="","",IF($B$5="Snowball",RANK(B10,$B$8:$B$15,1),RANK(C10,$C$8:$C$15,0))) -> 3 | F10: =IF(OR(A10="",D10=0),"",IF(C10=0,ROUNDUP(B10/D10,0),IF(D10<=B10*C10/12,"min too low",ROUNDUP(-LOG(1-B10*C10/12/D10)/LOG(1+C10/12),0)))) -> 44
A11: Student loan | B11: 18500 | C11: 0.055 | D11: 210 | E11: =IF(A11="","",IF($B$5="Snowball",RANK(B11,$B$8:$B$15,1),RANK(C11,$C$8:$C$15,0))) -> 4 | F11: =IF(OR(A11="",D11=0),"",IF(C11=0,ROUNDUP(B11/D11,0),IF(D11<=B11*C11/12,"min too low",ROUNDUP(-LOG(1-B11*C11/12/D11)/LOG(1+C11/12),0)))) -> 114
A12: Medical bill | B12: 900 | C12: 0 | D12: 50 | E12: =IF(A12="","",IF($B$5="Snowball",RANK(B12,$B$8:$B$15,1),RANK(C12,$C$8:$C$15,0))) -> 5 | F12: =IF(OR(A12="",D12=0),"",IF(C12=0,ROUNDUP(B12/D12,0),IF(D12<=B12*C12/12,"min too low",ROUNDUP(-LOG(1-B12*C12/12/D12)/LOG(1+C12/12),0)))) -> 18
E13: =IF(A13="","",IF($B$5="Snowball",RANK(B13,$B$8:$B$15,1),RANK(C13,$C$8:$C$15,0))) | F13: =IF(OR(A13="",D13=0),"",IF(C13=0,ROUNDUP(B13/D13,0),IF(D13<=B13*C13/12,"min too low",ROUNDUP(-LOG(1-B13*C13/12/D13)/LOG(1+C13/12),0))))
E14: =IF(A14="","",IF($B$5="Snowball",RANK(B14,$B$8:$B$15,1),RANK(C14,$C$8:$C$15,0))) | F14: =IF(OR(A14="",D14=0),"",IF(C14=0,ROUNDUP(B14/D14,0),IF(D14<=B14*C14/12,"min too low",ROUNDUP(-LOG(1-B14*C14/12/D14)/LOG(1+C14/12),0))))
E15: =IF(A15="","",IF($B$5="Snowball",RANK(B15,$B$8:$B$15,1),RANK(C15,$C$8:$C$15,0))) | F15: =IF(OR(A15="",D15=0),"",IF(C15=0,ROUNDUP(B15/D15,0),IF(D15<=B15*C15/12,"min too low",ROUNDUP(-LOG(1-B15*C15/12/D15)/LOG(1+C15/12),0))))
A16: TOTAL | B16: =SUM(B8:B15) -> 39800 | D16: =SUM(D8:D15) -> 800
A17: Total monthly toward debt | B17: =B16*0+D16+B4 -> 1200
A18: Debt-free in (months) | B18: =Schedule!$B$3 -> 39
A19: Total interest paid | B19: =Schedule!$B$4 -> 5112.0052

Sheet Schedule
A1: Payoff Schedule
A2: Simulated month by month. Balances after payment.
A3: Months to debt-free | B3: =IFERROR(MATCH(TRUE(),INDEX(L8:L127<=0.5,0),0),">120") -> 39
A4: Total interest paid | B4: =SUM(K8:K127) -> 5112.0052
A6: Month | B6: Available | C6: D1 bal | D6: D2 bal | E6: D3 bal | F6: D4 bal | G6: D5 bal | H6: D6 bal | I6: D7 bal | J6: D8 bal | K6: Interest this month | L6: Total balance
A7: =0 -> 0 | C7: =IF(Debts!$B$8="",0,Debts!$B$8) -> 6200 | D7: =IF(Debts!$B$9="",0,Debts!$B$9) -> 2400 | E7: =IF(Debts!$B$10="",0,Debts!$B$10) -> 11800 | F7: =IF(Debts!$B$11="",0,Debts!$B$11) -> 18500 | G7: =IF(Debts!$B$12="",0,Debts!$B$12) -> 900 | H7: =IF(Debts!$B$13="",0,Debts!$B$13) -> 0 | I7: =IF(Debts!$B$14="",0,Debts!$B$14) -> 0 | J7: =IF(Debts!$B$15="",0,Debts!$B$15) -> 0 | K7: =0 -> 0 | L7: =SUM(C7:J7) -> 39800
A8: =1 -> 1 | B8: =IF(L7<=0,0,Debts!$D$16+Debts!$B$4) -> 1200 | C8: =IF(C7<=0,0,MAX(0,C7*(1+Debts!$C$8/12)-MIN(C7*(1+Debts!$C$8/12),Debts!$D$8)-IF(AND(C7>0,Debts!$E$8=MIN(IF(C7>0,Debts!$E$8,999),IF(D7>0,Debts!$E$9,999),IF(E7>0,Debts!$E$10,999),IF(F7>0,Debts!$E$11,999),IF(G7>0,Debts!$E$12,999),IF(H7>0,Debts!$E$13,999),IF(I7>0,Debts!$E$14,999),IF(J7>0,Debts!$E$15,999))),MAX(0,(B8-(MIN(C7+0,C7*(1+Debts!$C$8/12))*0+MIN(C7*(1+Debts!$C$8/12),Debts!$D$8)+MIN(C7+0,D7*(1+Debts!$C$9/12))*0+MIN(D7*(1+Debts!$C$9/12),Debts!$D$9)+MIN(C7+0,E7*(1+Debts!$C$10/12))*0+MIN(E7*(1+Debts!$C$10/12),Debts!$D$10)+MIN(C7+0,F7*(1+Debts!$C$11/12))*0+MIN(F7*(1+Debts!$C$11/12),Debts!$D$11)+MIN(C7+0,G7*(1+Debts!$C$12/12))*0+MIN(G7*(1+Debts!$C$12/12),Debts!$D$12)+MIN(C7+0,H7*(1+Debts!$C$13/12))*0+MIN(H7*(1+Debts!$C$13/12),Debts!$D$13)+MIN(C7+0,I7*(1+Debts!$C$14/12))*0+MIN(I7*(1+Debts!$C$14/12),Debts!$D$14)+MIN(C7+0,J7*(1+Debts!$C$15/12))*0+MIN(J7*(1+Debts!$C$15/12),Debts!$D$15)))),0))) -> 5773.65 | D8: =IF(D7<=0,0,MAX(0,D7*(1+Debts!$C$9/12)-MIN(D7*(1+Debts!$C$9/12),Debts!$D$9)-IF(AND(D7>0,Debts!$E$9=MIN(IF(C7>0,Debts!$E$8,999),IF(D7>0,Debts!$E$9,999),IF(E7>0,Debts!$E$10,999),IF(F7>0,Debts!$E$11,999),IF(G7>0,Debts!$E$12,999),IF(H7>0,Debts!$E$13,999),IF(I7>0,Debts!$E$14,999),IF(J7>0,Debts!$E$15,999))),MAX(0,(B8-(MIN(C7+0,C7*(1+Debts!$C$8/12))*0+MIN(C7*(1+Debts!$C$8/12),Debts!$D$8)+MIN(C7+0,D7*(1+Debts!$C$9/12))*0+MIN(D7*(1+Debts!$C$9/12),Debts!$D$9)+MIN(C7+0,E7*(1+Debts!$C$10/12))*0+MIN(E7*(1+Debts!$C$10/12),Debts!$D$10)+MIN(C7+0,F7*(1+Debts!$C$11/12))*0+MIN(F7*(1+Debts!$C$11/12),Debts!$D$11)+MIN(C7+0,G7*(1+Debts!$C$12/12))*0+MIN(G7*(1+Debts!$C$12/12),Debts!$D$12)+MIN(C7+0,H7*(1+Debts!$C$13/12))*0+MIN(H7*(1+Debts!$C$13/12),Debts!$D$13)+MIN(C7+0,I7*(1+Debts!$C$14/12))*0+MIN(I7*(1+Debts!$C$14/12),Debts!$D$14)+MIN(C7+0,J7*(1+Debts!$C$15/12))*0+MIN(J7*(1+Debts!$C$15/12),Debts!$D$15)))),0))) -> 2368.8 | E8: =IF(E7<=0,0,MAX(0,E7*(1+Debts!$C$10/12)-MIN(E7*(1+Debts!$C$10/12),Debts!$D$10)-IF(AND(E7>0,Debts!$E$10=MIN(IF(C7>0,Debts!$E$8,999),IF(D7>0,Debts!$E$9,999),IF(E7>0,Debts!$E$10,999),IF(F7>0,Debts!$E$11,999),IF(G7>0,Debts!$E$12,999),IF(H7>0,Debts!$E$13,999),IF(I7>0,Debts!$E$14,999),IF(J7>0,Debts!$E$15,999))),MAX(0,(B8-(MIN(C7+0,C7*(1+Debts!$C$8/12))*0+MIN(C7*(1+Debts!$C$8/12),Debts!$D$8)+MIN(C7+0,D7*(1+Debts!$C$9/12))*0+MIN(D7*(1+Debts!$C$9/12),Debts!$D$9)+MIN(C7+0,E7*(1+Debts!$C$10/12))*0+MIN(E7*(1+Debts!$C$10/12),Debts!$D$10)+MIN(C7+0,F7*(1+Debts!$C$11/12))*0+MIN(F7*(1+Debts!$C$11/12),Debts!$D$11)+MIN(C7+0,G7*(1+Debts!$C$12/12))*0+MIN(G7*(1+Debts!$C$12/12),Debts!$D$12)+MIN(C7+0,H7*(1+Debts!$C$13/12))*0+MIN(H7*(1+Debts!$C$13/12),Debts!$D$13)+MIN(C7+0,I7*(1+Debts!$C$14/12))*0+MIN(I7*(1+Debts!$C$14/12),Debts!$D$14)+MIN(C7+0,J7*(1+Debts!$C$15/12))*0+MIN(J7*(1+Debts!$C$15/12),Debts!$D$15)))),0))) -> 11557.85 | F8: =IF(F7<=0,0,MAX(0,F7*(1+Debts!$C$11/12)-MIN(F7*(1+Debts!$C$11/12),Debts!$D$11)-IF(AND(F7>0,Debts!$E$11=MIN(IF(C7>0,Debts!$E$8,999),IF(D7>0,Debts!$E$9,999),IF(E7>0,Debts!$E$10,999),IF(F7>0,Debts!$E$11,999),IF(G7>0,Debts!$E$12,999),IF(H7>0,Debts!$E$13,999),IF(I7>0,Debts!$E$14,999),IF(J7>0,Debts!$E$15,999))),MAX(0,(B8-(MIN(C7+0,C7*(1+Debts!$C$8/12))*0+MIN(C7*(1+Debts!$C$8/12),Debts!$D$8)+MIN(C7+0,D7*(1+Debts!$C$9/12))*0+MIN(D7*(1+Debts!$C$9/12),Debts!$D$9)+MIN(C7+0,E7*(1+Debts!$C$10/12))*0+MIN(E7*(1+Debts!$C$10/12),Debts!$D$10)+MIN(C7+0,F7*(1+Debts!$C$11/12))*0+MIN(F7*(1+Debts!$C$11/12),Debts!$D$11)+MIN(C7+0,G7*(1+Debts!$C$12/12))*0+MIN(G7*(1+Debts!$C$12/12),Debts!$D$12)+MIN(C7+0,H7*(1+Debts!$C$13/12))*0+MIN(H7*(1+Debts!$C$13/12),Debts!$D$13)+MIN(C7+0,I7*(1+Debts!$C$14/12))*0+MIN(I7*(1+Debts!$C$14/12),Debts!$D$14)+MIN(C7+0,J7*(1+Debts!$C$15/12))*0+MIN(J7*(1+Debts!$C$15/12),Debts!$D$15)))),0))) -> 18374.792 | G8: =IF(G7<=0,0,MAX(0,G7*(1+Debts!$C$12/12)-MIN(G7*(1+Debts!$C$12/12),Debts!$D$12)-IF(AND(G7>0,Debts!$E$12=MIN(IF(C7>0,Debts!$E$8,999),IF(D7>0,Debts!$E$9,999),IF(E7>0,Debts!$E$10,999),IF(F7>0,Debts!$E$11,999),IF(G7>0,Debts!$E$12,999),IF(H7>0,Debts!$E$13,999),IF(I7>0,Debts!$E$14,999),IF(J7>0,Debts!$E$15,999))),MAX(0,(B8-(MIN(C7+0,C7*(1+Debts!$C$8/12))*0+MIN(C7*(1+Debts!$C$8/12),Debts!$D$8)+MIN(C7+0,D7*(1+Debts!$C$9/12))*0+MIN(D7*(1+Debts!$C$9/12),Debts!$D$9)+MIN(C7+0,E7*(1+Debts!$C$10/12))*0+MIN(E7*(1+Debts!$C$10/12),Debts!$D$10)+MIN(C7+0,F7*(1+Debts!$C$11/12))*0+MIN(F7*(1+Debts!$C$11/12),Debts!$D$11)+MIN(C7+0,G7*(1+Debts!$C$12/12))*0+MIN(G7*(1+Debts!$C$12/12),Debts!$D$12)+MIN(C7+0,H7*(1+Debts!$C$13/12))*0+MIN(H7*(1+Debts!$C$13/12),Debts!$D$13)+MIN(C7+0,I7*(1+Debts!$C$14/12))*0+MIN(I7*(1+Debts!$C$14/12),Debts!$D$14)+MIN(C7+0,J7*(1+Debts!$C$15/12))*0+MIN(J7*(1+Debts!$C$15/12),Debts!$D$15)))),0))) -> 850 | H8: =IF(H7<=0,0,MAX(0,H7*(1+Debts!$C$13/12)-MIN(H7*(1+Debts!$C$13/12),Debts!$D$13)-IF(AND(H7>0,Debts!$E$13=MIN(IF(C7>0,Debts!$E$8,999),IF(D7>0,Debts!$E$9,999),IF(E7>0,Debts!$E$10,999),IF(F7>0,Debts!$E$11,999),IF(G7>0,Debts!$E$12,999),IF(H7>0,Debts!$E$13,999),IF(I7>0,Debts!$E$14,999),IF(J7>0,Debts!$E$15,999))),MAX(0,(B8-(MIN(C7+0,C7*(1+Debts!$C$8/12))*0+MIN(C7*(1+Debts!$C$8/12),Debts!$D$8)+MIN(C7+0,D7*(1+Debts!$C$9/12))*0+MIN(D7*(1+Debts!$C$9/12),Debts!$D$9)+MIN(C7+0,E7*(1+Debts!$C$10/12))*0+MIN(E7*(1+Debts!$C$10/12),Debts!$D$10)+MIN(C7+0,F7*(1+Debts!$C$11/12))*0+MIN(F7*(1+Debts!$C$11/12),Debts!$D$11)+MIN(C7+0,G7*(1+Debts!$C$12/12))*0+MIN(G7*(1+Debts!$C$12/12),Debts!$D$12)+MIN(C7+0,H7*(1+Debts!$C$13/12))*0+MIN(H7*(1+Debts!$C$13/12),Debts!$D$13)+MIN(C7+0,I7*(1+Debts!$C$14/12))*0+MIN(I7*(1+Debts!$C$14/12),Debts!$D$14)+MIN(C7+0,J7*(1+Debts!$C$15/12))*0+MIN(J7*(1+Debts!$C$15/12),Debts!$D$15)))),0))) -> 0 | I8: =IF(I7<=0,0,MAX(0,I7*(1+Debts!$C$14/12)-MIN(I7*(1+Debts!$C$14/12),Debts!$D$14)-IF(AND(I7>0,Debts!$E$14=MIN(IF(C7>0,Debts!$E$8,999),IF(D7>0,Debts!$E$9,999),IF(E7>0,Debts!$E$10,999),IF(F7>0,Debts!$E$11,999),IF(G7>0,Debts!$E$12,999),IF(H7>0,Debts!$E$13,999),IF(I7>0,Debts!$E$14,999),IF(J7>0,Debts!$E$15,999))),MAX(0,(B8-(MIN(C7+0,C7*(1+Debts!$C$8/12))*0+MIN(C7*(1+Debts!$C$8/12),Debts!$D$8)+MIN(C7+0,D7*(1+Debts!$C$9/12))*0+MIN(D7*(1+Debts!$C$9/12),Debts!$D$9)+MIN(C7+0,E7*(1+Debts!$C$10/12))*0+MIN(E7*(1+Debts!$C$10/12),Debts!$D$10)+MIN(C7+0,F7*(1+Debts!$C$11/12))*0+MIN(F7*(1+Debts!$C$11/12),Debts!$D$11)+MIN(C7+0,G7*(1+Debts!$C$12/12))*0+MIN(G7*(1+Debts!$C$12/12),Debts!$D$12)+MIN(C7+0,H7*(1+Debts!$C$13/12))*0+MIN(H7*(1+Debts!$C$13/12),Debts!$D$13)+MIN(C7+0,I7*(1+Debts!$C$14/12))*0+MIN(I7*(1+Debts!$C$14/12),Debts!$D$14)+MIN(C7+0,J7*(1+Debts!$C$15/12))*0+MIN(J7*(1+Debts!$C$15/12),Debts!$D$15)))),0))) -> 0 | J8: =IF(J7<=0,0,MAX(0,J7*(1+Debts!$C$15/12)-MIN(J7*(1+Debts!$C$15/12),Debts!$D$15)-IF(AND(J7>0,Debts!$E$15=MIN(IF(C7>0,Debts!$E$8,999),IF(D7>0,Debts!$E$9,999),IF(E7>0,Debts!$E$10,999),IF(F7>0,Debts!$E$11,999),IF(G7>0,Debts!$E$12,999),IF(H7>0,Debts!$E$13,999),IF(I7>0,Debts!$E$14,999),IF(J7>0,Debts!$E$15,999))),MAX(0,(B8-(MIN(C7+0,C7*(1+Debts!$C$8/12))*0+MIN(C7*(1+Debts!$C$8/12),Debts!$D$8)+MIN(C7+0,D7*(1+Debts!$C$9/12))*0+MIN(D7*(1+Debts!$C$9/12),Debts!$D$9)+MIN(C7+0,E7*(1+Debts!$C$10/12))*0+MIN(E7*(1+Debts!$C$10/12),Debts!$D$10)+MIN(C7+0,F7*(1+Debts!$C$11/12))*0+MIN(F7*(1+Debts!$C$11/12),Debts!$D$11)+MIN(C7+0,G7*(1+Debts!$C$12/12))*0+MIN(G7*(1+Debts!$C$12/12),Debts!$D$12)+MIN(C7+0,H7*(1+Debts!$C$13/12))*0+MIN(H7*(1+Debts!$C$13/12),Debts!$D$13)+MIN(C7+0,I7*(1+Debts!$C$14/12))*0+MIN(I7*(1+Debts!$C$14/12),Debts!$D$14)+MIN(C7+0,J7*(1+Debts!$C$15/12))*0+MIN(J7*(1+Debts!$C$15/12),Debts!$D$15)))),0))) -> 0 | K8: =IF(C7>0,C7*Debts!$C$8/12,0)+IF(D7>0,D7*Debts!$C$9/12,0)+IF(E7>0,E7*Debts!$C$10/12,0)+IF(F7>0,F7*Debts!$C$11/12,0)+IF(G7>0,G7*Debts!$C$12/12,0)+IF(H7>0,H7*Debts!$C$13/12,0)+IF(I7>0,I7*Debts!$C$14/12,0)+IF(J7>0,J7*Debts!$C$15/12,0) -> 325.09167 | L8: =SUM(C8:J8) -> 38925.092
A9: =2 -> 2 | B9: =IF(L8<=0,0,Debts!$D$16+Debts!$B$4) -> 1200 | C9: =IF(C8<=0,0,MAX(0,C8*(1+Debts!$C$8/12)-MIN(C8*(1+Debts!$C$8/12),Debts!$D$8)-IF(AND(C8>0,Debts!$E$8=MIN(IF(C8>0,Debts!$E$8,999),IF(D8>0,Debts!$E$9,999),IF(E8>0,Debts!$E$10,999),IF(F8>0,Debts!$E$11,999),IF(G8>0,Debts!$E$12,999),IF(H8>0,Debts!$E$13,999),IF(I8>0,Debts!$E$14,999),IF(J8>0,Debts!$E$15,999))),MAX(0,(B9-(MIN(C8+0,C8*(1+Debts!$C$8/12))*0+MIN(C8*(1+Debts!$C$8/12),Debts!$D$8)+MIN(C8+0,D8*(1+Debts!$C$9/12))*0+MIN(D8*(1+Debts!$C$9/12),Debts!$D$9)+MIN(C8+0,E8*(1+Debts!$C$10/12))*0+MIN(E8*(1+Debts!$C$10/12),Debts!$D$10)+MIN(C8+0,F8*(1+Debts!$C$11/12))*0+MIN(F8*(1+Debts!$C$11/12),Debts!$D$11)+MIN(C8+0,G8*(1+Debts!$C$12/12))*0+MIN(G8*(1+Debts!$C$12/12),Debts!$D$12)+MIN(C8+0,H8*(1+Debts!$C$13/12))*0+MIN(H8*(1+Debts!$C$13/12),Debts!$D$13)+MIN(C8+0,I8*(1+Debts!$C$14/12))*0+MIN(I8*(1+Debts!$C$14/12),Debts!$D$14)+MIN(C8+0,J8*(1+Debts!$C$15/12))*0+MIN(J8*(1+Debts!$C$15/12),Debts!$D$15)))),0))) -> 5338.4532 | D9: =IF(D8<=0,0,MAX(0,D8*(1+Debts!$C$9/12)-MIN(D8*(1+Debts!$C$9/12),Debts!$D$9)-IF(AND(D8>0,Debts!$E$9=MIN(IF(C8>0,Debts!$E$8,999),IF(D8>0,Debts!$E$9,999),IF(E8>0,Debts!$E$10,999),IF(F8>0,Debts!$E$11,999),IF(G8>0,Debts!$E$12,999),IF(H8>0,Debts!$E$13,999),IF(I8>0,Debts!$E$14,999),IF(J8>0,Debts!$E$15,999))),MAX(0,(B9-(MIN(C8+0,C8*(1+Debts!$C$8/12))*0+MIN(C8*(1+Debts!$C$8/12),Debts!$D$8)+MIN(C8+0,D8*(1+Debts!$C$9/12))*0+MIN(D8*(1+Debts!$C$9/12),Debts!$D$9)+MIN(C8+0,E8*(1+Debts!$C$10/12))*0+MIN(E8*(1+Debts!$C$10/12),Debts!$D$10)+MIN(C8+0,F8*(1+Debts!$C$11/12))*0+MIN(F8*(1+Debts!$C$11/12),Debts!$D$11)+MIN(C8+0,G8*(1+Debts!$C$12/12))*0+MIN(G8*(1+Debts!$C$12/12),Debts!$D$12)+MIN(C8+0,H8*(1+Debts!$C$13/12))*0+MIN(H8*(1+Debts!$C$13/12),Debts!$D$13)+MIN(C8+0,I8*(1+Debts!$C$14/12))*0+MIN(I8*(1+Debts!$C$14/12),Debts!$D$14)+MIN(C8+0,J8*(1+Debts!$C$15/12))*0+MIN(J8*(1+Debts!$C$15/12),Debts!$D$15)))),0))) -> 2337.0306 | E9: =IF(E8<=0,0,MAX(0,E8*(1+Debts!$C$10/12)-MIN(E8*(1+Debts!$C$10/12),Debts!$D$10)-IF(AND(E8>0,Debts!$E$10=MIN(IF(C8>0,Debts!$E$8,999),IF(D8>0,Debts!$E$9,999),IF(E8>0,Debts!$E$10,999),IF(F8>0,Debts!$E$11,999),IF(G8>0,Debts!$E$12,999),IF(H8>0,Debts!$E$13,999),IF(I8>0,Debts!$E$14,999),IF(J8>0,Debts!$E$15,999))),MAX(0,(B9-(MIN(C8+0,C8*(1+Debts!$C$8/12))*0+MIN(C8*(1+Debts!$C$8/12),Debts!$D$8)+MIN(C8+0,D8*(1+Debts!$C$9/12))*0+MIN(D8*(1+Debts!$C$9/12),Debts!$D$9)+MIN(C8+0,E8*(1+Debts!$C$10/12))*0+MIN(E8*(1+Debts!$C$10/12),Debts!$D$10)+MIN(C8+0,F8*(1+Debts!$C$11/12))*0+MIN(F8*(1+Debts!$C$11/12),Debts!$D$11)+MIN(C8+0,G8*(1+Debts!$C$12/12))*0+MIN(G8*(1+Debts!$C$12/12),Debts!$D$12)+MIN(C8+0,H8*(1+Debts!$C$13/12))*0+MIN(H8*(1+Debts!$C$13/12),Debts!$D$13)+MIN(C8+0,I8*(1+Debts!$C$14/12))*0+MIN(I8*(1+Debts!$C$14/12),Debts!$D$14)+MIN(C8+0,J8*(1+Debts!$C$15/12))*0+MIN(J8*(1+Debts!$C$15/12),Debts!$D$15)))),0))) -> 11314.308 | F9: =IF(F8<=0,0,MAX(0,F8*(1+Debts!$C$11/12)-MIN(F8*(1+Debts!$C$11/12),Debts!$D$11)-IF(AND(F8>0,Debts!$E$11=MIN(IF(C8>0,Debts!$E$8,999),IF(D8>0,Debts!$E$9,999),IF(E8>0,Debts!$E$10,999),IF(F8>0,Debts!$E$11,999),IF(G8>0,Debts!$E$12,999),IF(H8>0,Debts!$E$13,999),IF(I8>0,Debts!$E$14,999),IF(J8>0,Debts!$E$15,999))),MAX(0,(B9-(MIN(C8+0,C8*(1+Debts!$C$8/12))*0+MIN(C8*(1+Debts!$C$8/12),Debts!$D$8)+MIN(C8+0,D8*(1+Debts!$C$9/12))*0+MIN(D8*(1+Debts!$C$9/12),Debts!$D$9)+MIN(C8+0,E8*(1+Debts!$C$10/12))*0+MIN(E8*(1+Debts!$C$10/12),Debts!$D$10)+MIN(C8+0,F8*(1+Debts!$C$11/12))*0+MIN(F8*(1+Debts!$C$11/12),Debts!$D$11)+MIN(C8+0,G8*(1+Debts!$C$12/12))*0+MIN(G8*(1+Debts!$C$12/12),Debts!$D$12)+MIN(C8+0,H8*(1+Debts!$C$13/12))*0+MIN(H8*(1+Debts!$C$13/12),Debts!$D$13)+MIN(C8+0,I8*(1+Debts!$C$14/12))*0+MIN(I8*(1+Debts!$C$14/12),Debts!$D$14)+MIN(C8+0,J8*(1+Debts!$C$15/12))*0+MIN(J8*(1+Debts!$C$15/12),Debts!$D$15)))),0))) -> 18249.009 | G9: =IF(G8<=0,0,MAX(0,G8*(1+Debts!$C$12/12)-MIN(G8*(1+Debts!$C$12/12),Debts!$D$12)-IF(AND(G8>0,Debts!$E$12=MIN(IF(C8>0,Debts!$E$8,999),IF(D8>0,Debts!$E$9,999),IF(E8>0,Debts!$E$10,999),IF(F8>0,Debts!$E$11,999),IF(G8>0,Debts!$E$12,999),IF(H8>0,Debts!$E$13,999),IF(I8>0,Debts!$E$14,999),IF(J8>0,Debts!$E$15,999))),MAX(0,(B9-(MIN(C8+0,C8*(1+Debts!$C$8/12))*0+MIN(C8*(1+Debts!$C$8/12),Debts!$D$8)+MIN(C8+0,D8*(1+Debts!$C$9/12))*0+MIN(D8*(1+Debts!$C$9/12),Debts!$D$9)+MIN(C8+0,E8*(1+Debts!$C$10/12))*0+MIN(E8*(1+Debts!$C$10/12),Debts!$D$10)+MIN(C8+0,F8*(1+Debts!$C$11/12))*0+MIN(F8*(1+Debts!$C$11/12),Debts!$D$11)+MIN(C8+0,G8*(1+Debts!$C$12/12))*0+MIN(G8*(1+Debts!$C$12/12),Debts!$D$12)+MIN(C8+0,H8*(1+Debts!$C$13/12))*0+MIN(H8*(1+Debts!$C$13/12),Debts!$D$13)+MIN(C8+0,I8*(1+Debts!$C$14/12))*0+MIN(I8*(1+Debts!$C$14/12),Debts!$D$14)+MIN(C8+0,J8*(1+Debts!$C$15/12))*0+MIN(J8*(1+Debts!$C$15/12),Debts!$D$15)))),0))) -> 800 | H9: =IF(H8<=0,0,MAX(0,H8*(1+Debts!$C$13/12)-MIN(H8*(1+Debts!$C$13/12),Debts!$D$13)-IF(AND(H8>0,Debts!$E$13=MIN(IF(C8>0,Debts!$E$8,999),IF(D8>0,Debts!$E$9,999),IF(E8>0,Debts!$E$10,999),IF(F8>0,Debts!$E$11,999),IF(G8>0,Debts!$E$12,999),IF(H8>0,Debts!$E$13,999),IF(I8>0,Debts!$E$14,999),IF(J8>0,Debts!$E$15,999))),MAX(0,(B9-(MIN(C8+0,C8*(1+Debts!$C$8/12))*0+MIN(C8*(1+Debts!$C$8/12),Debts!$D$8)+MIN(C8+0,D8*(1+Debts!$C$9/12))*0+MIN(D8*(1+Debts!$C$9/12),Debts!$D$9)+MIN(C8+0,E8*(1+Debts!$C$10/12))*0+MIN(E8*(1+Debts!$C$10/12),Debts!$D$10)+MIN(C8+0,F8*(1+Debts!$C$11/12))*0+MIN(F8*(1+Debts!$C$11/12),Debts!$D$11)+MIN(C8+0,G8*(1+Debts!$C$12/12))*0+MIN(G8*(1+Debts!$C$12/12),Debts!$D$12)+MIN(C8+0,H8*(1+Debts!$C$13/12))*0+MIN(H8*(1+Debts!$C$13/12),Debts!$D$13)+MIN(C8+0,I8*(1+Debts!$C$14/12))*0+MIN(I8*(1+Debts!$C$14/12),Debts!$D$14)+MIN(C8+0,J8*(1+Debts!$C$15/12))*0+MIN(J8*(1+Debts!$C$15/12),Debts!$D$15)))),0))) -> 0 | I9: =IF(I8<=0,0,MAX(0,I8*(1+Debts!$C$14/12)-MIN(I8*(1+Debts!$C$14/12),Debts!$D$14)-IF(AND(I8>0,Debts!$E$14=MIN(IF(C8>0,Debts!$E$8,999),IF(D8>0,Debts!$E$9,999),IF(E8>0,Debts!$E$10,999),IF(F8>0,Debts!$E$11,999),IF(G8>0,Debts!$E$12,999),IF(H8>0,Debts!$E$13,999),IF(I8>0,Debts!$E$14,999),IF(J8>0,Debts!$E$15,999))),MAX(0,(B9-(MIN(C8+0,C8*(1+Debts!$C$8/12))*0+MIN(C8*(1+Debts!$C$8/12),Debts!$D$8)+MIN(C8+0,D8*(1+Debts!$C$9/12))*0+MIN(D8*(1+Debts!$C$9/12),Debts!$D$9)+MIN(C8+0,E8*(1+Debts!$C$10/12))*0+MIN(E8*(1+Debts!$C$10/12),Debts!$D$10)+MIN(C8+0,F8*(1+Debts!$C$11/12))*0+MIN(F8*(1+Debts!$C$11/12),Debts!$D$11)+MIN(C8+0,G8*(1+Debts!$C$12/12))*0+MIN(G8*(1+Debts!$C$12/12),Debts!$D$12)+MIN(C8+0,H8*(1+Debts!$C$13/12))*0+MIN(H8*(1+Debts!$C$13/12),Debts!$D$13)+MIN(C8+0,I8*(1+Debts!$C$14/12))*0+MIN(I8*(1+Debts!$C$14/12),Debts!$D$14)+MIN(C8+0,J8*(1+Debts!$C$15/12))*0+MIN(J8*(1+Debts!$C$15/12),Debts!$D$15)))),0))) -> 0 | J9: =IF(J8<=0,0,MAX(0,J8*(1+Debts!$C$15/12)-MIN(J8*(1+Debts!$C$15/12),Debts!$D$15)-IF(AND(J8>0,Debts!$E$15=MIN(IF(C8>0,Debts!$E$8,999),IF(D8>0,Debts!$E$9,999),IF(E8>0,Debts!$E$10,999),IF(F8>0,Debts!$E$11,999),IF(G8>0,Debts!$E$12,999),IF(H8>0,Debts!$E$13,999),IF(I8>0,Debts!$E$14,999),IF(J8>0,Debts!$E$15,999))),MAX(0,(B9-(MIN(C8+0,C8*(1+Debts!$C$8/12))*0+MIN(C8*(1+Debts!$C$8/12),Debts!$D$8)+MIN(C8+0,D8*(1+Debts!$C$9/12))*0+MIN(D8*(1+Debts!$C$9/12),Debts!$D$9)+MIN(C8+0,E8*(1+Debts!$C$10/12))*0+MIN(E8*(1+Debts!$C$10/12),Debts!$D$10)+MIN(C8+0,F8*(1+Debts!$C$11/12))*0+MIN(F8*(1+Debts!$C$11/12),Debts!$D$11)+MIN(C8+0,G8*(1+Debts!$C$12/12))*0+MIN(G8*(1+Debts!$C$12/12),Debts!$D$12)+MIN(C8+0,H8*(1+Debts!$C$13/12))*0+MIN(H8*(1+Debts!$C$13/12),Debts!$D$13)+MIN(C8+0,I8*(1+Debts!$C$14/12))*0+MIN(I8*(1+Debts!$C$14/12),Debts!$D$14)+MIN(C8+0,J8*(1+Debts!$C$15/12))*0+MIN(J8*(1+Debts!$C$15/12),Debts!$D$15)))),0))) -> 0 | K9: =IF(C8>0,C8*Debts!$C$8/12,0)+IF(D8>0,D8*Debts!$C$9/12,0)+IF(E8>0,E8*Debts!$C$10/12,0)+IF(F8>0,F8*Debts!$C$11/12,0)+IF(G8>0,G8*Debts!$C$12/12,0)+IF(H8>0,H8*Debts!$C$13/12,0)+IF(I8>0,I8*Debts!$C$14/12,0)+IF(J8>0,J8*Debts!$C$15/12,0) -> 313.70927 | L9: =SUM(C9:J9) -> 38038.801
A10: =3 -> 3 | B10: =IF(L9<=0,0,Debts!$D$16+Debts!$B$4) -> 1200 | C10: =IF(C9<=0,0,MAX(0,C9*(1+Debts!$C$8/12)-MIN(C9*(1+Debts!$C$8/12),Debts!$D$8)-IF(AND(C9>0,Debts!$E$8=MIN(IF(C9>0,Debts!$E$8,999),IF(D9>0,Debts!$E$9,999),IF(E9>0,Debts!$E$10,999),IF(F9>0,Debts!$E$11,999),IF(G9>0,Debts!$E$12,999),IF(H9>0,Debts!$E$13,999),IF(I9>0,Debts!$E$14,999),IF(J9>0,Debts!$E$15,999))),MAX(0,(B10-(MIN(C9+0,C9*(1+Debts!$C$8/12))*0+MIN(C9*(1+Debts!$C$8/12),Debts!$D$8)+MIN(C9+0,D9*(1+Debts!$C$9/12))*0+MIN(D9*(1+Debts!$C$9/12),Debts!$D$9)+MIN(C9+0,E9*(1+Debts!$C$10/12))*0+MIN(E9*(1+Debts!$C$10/12),Debts!$D$10)+MIN(C9+0,F9*(1+Debts!$C$11/12))*0+MIN(F9*(1+Debts!$C$11/12),Debts!$D$11)+MIN(C9+0,G9*(1+Debts!$C$12/12))*0+MIN(G9*(1+Debts!$C$12/12),Debts!$D$12)+MIN(C9+0,H9*(1+Debts!$C$13/12))*0+MIN(H9*(1+Debts!$C$13/12),Debts!$D$13)+MIN(C9+0,I9*(1+Debts!$C$14/12))*0+MIN(I9*(1+Debts!$C$14/12),Debts!$D$14)+MIN(C9+0,J9*(1+Debts!$C$15/12))*0+MIN(J9*(1+Debts!$C$15/12),Debts!$D$15)))),0))) -> 4894.2261 | D10: =IF(D9<=0,0,MAX(0,D9*(1+Debts!$C$9/12)-MIN(D9*(1+Debts!$C$9/12),Debts!$D$9)-IF(AND(D9>0,Debts!$E$9=MIN(IF(C9>0,Debts!$E$8,999),IF(D9>0,Debts!$E$9,999),IF(E9>0,Debts!$E$10,999),IF(F9>0,Debts!$E$11,999),IF(G9>0,Debts!$E$12,999),IF(H9>0,Debts!$E$13,999),IF(I9>0,Debts!$E$14,999),IF(J9>0,Debts!$E$15,999))),MAX(0,(B10-(MIN(C9+0,C9*(1+Debts!$C$8/12))*0+MIN(C9*(1+Debts!$C$8/12),Debts!$D$8)+MIN(C9+0,D9*(1+Debts!$C$9/12))*0+MIN(D9*(1+Debts!$C$9/12),Debts!$D$9)+MIN(C9+0,E9*(1+Debts!$C$10/12))*0+MIN(E9*(1+Debts!$C$10/12),Debts!$D$10)+MIN(C9+0,F9*(1+Debts!$C$11/12))*0+MIN(F9*(1+Debts!$C$11/12),Debts!$D$11)+MIN(C9+0,G9*(1+Debts!$C$12/12))*0+MIN(G9*(1+Debts!$C$12/12),Debts!$D$12)+MIN(C9+0,H9*(1+Debts!$C$13/12))*0+MIN(H9*(1+Debts!$C$13/12),Debts!$D$13)+MIN(C9+0,I9*(1+Debts!$C$14/12))*0+MIN(I9*(1+Debts!$C$14/12),Debts!$D$14)+MIN(C9+0,J9*(1+Debts!$C$15/12))*0+MIN(J9*(1+Debts!$C$15/12),Debts!$D$15)))),0))) -> 2304.6814 | E10: =IF(E9<=0,0,MAX(0,E9*(1+Debts!$C$10/12)-MIN(E9*(1+Debts!$C$10/12),Debts!$D$10)-IF(AND(E9>0,Debts!$E$10=MIN(IF(C9>0,Debts!$E$8,999),IF(D9>0,Debts!$E$9,999),IF(E9>0,Debts!$E$10,999),IF(F9>0,Debts!$E$11,999),IF(G9>0,Debts!$E$12,999),IF(H9>0,Debts!$E$13,999),IF(I9>0,Debts!$E$14,999),IF(J9>0,Debts!$E$15,999))),MAX(0,(B10-(MIN(C9+0,C9*(1+Debts!$C$8/12))*0+MIN(C9*(1+Debts!$C$8/12),Debts!$D$8)+MIN(C9+0,D9*(1+Debts!$C$9/12))*0+MIN(D9*(1+Debts!$C$9/12),Debts!$D$9)+MIN(C9+0,E9*(1+Debts!$C$10/12))*0+MIN(E9*(1+Debts!$C$10/12),Debts!$D$10)+MIN(C9+0,F9*(1+Debts!$C$11/12))*0+MIN(F9*(1+Debts!$C$11/12),Debts!$D$11)+MIN(C9+0,G9*(1+Debts!$C$12/12))*0+MIN(G9*(1+Debts!$C$12/12),Debts!$D$12)+MIN(C9+0,H9*(1+Debts!$C$13/12))*0+MIN(H9*(1+Debts!$C$13/12),Debts!$D$13)+MIN(C9+0,I9*(1+Debts!$C$14/12))*0+MIN(I9*(1+Debts!$C$14/12),Debts!$D$14)+MIN(C9+0,J9*(1+Debts!$C$15/12))*0+MIN(J9*(1+Debts!$C$15/12),Debts!$D$15)))),0))) -> 11069.365 | F10: =IF(F9<=0,0,MAX(0,F9*(1+Debts!$C$11/12)-MIN(F9*(1+Debts!$C$11/12),Debts!$D$11)-IF(AND(F9>0,Debts!$E$11=MIN(IF(C9>0,Debts!$E$8,999),IF(D9>0,Debts!$E$9,999),IF(E9>0,Debts!$E$10,999),IF(F9>0,Debts!$E$11,999),IF(G9>0,Debts!$E$12,999),IF(H9>0,Debts!$E$13,999),IF(I9>0,Debts!$E$14,999),IF(J9>0,Debts!$E$15,999))),MAX(0,(B10-(MIN(C9+0,C9*(1+Debts!$C$8/12))*0+MIN(C9*(1+Debts!$C$8/12),Debts!$D$8)+MIN(C9+0,D9*(1+Debts!$C$9/12))*0+MIN(D9*(1+Debts!$C$9/12),Debts!$D$9)+MIN(C9+0,E9*(1+Debts!$C$10/12))*0+MIN(E9*(1+Debts!$C$10/12),Debts!$D$10)+MIN(C9+0,F9*(1+Debts!$C$11/12))*0+MIN(F9*(1+Debts!$C$11/12),Debts!$D$11)+MIN(C9+0,G9*(1+Debts!$C$12/12))*0+MIN(G9*(1+Debts!$C$12/12),Debts!$D$12)+MIN(C9+0,H9*(1+Debts!$C$13/12))*0+MIN(H9*(1+Debts!$C$13/12),Debts!$D$13)+MIN(C9+0,I9*(1+Debts!$C$14/12))*0+MIN(I9*(1+Debts!$C$14/12),Debts!$D$14)+MIN(C9+0,J9*(1+Debts!$C$15/12))*0+MIN(J9*(1+Debts!$C$15/12),Debts!$D$15)))),0))) -> 18122.651 | G10: =IF(G9<=0,0,MAX(0,G9*(1+Debts!$C$12/12)-MIN(G9*(1+Debts!$C$12/12),Debts!$D$12)-IF(AND(G9>0,Debts!$E$12=MIN(IF(C9>0,Debts!$E$8,999),IF(D9>0,Debts!$E$9,999),IF(E9>0,Debts!$E$10,999),IF(F9>0,Debts!$E$11,999),IF(G9>0,Debts!$E$12,999),IF(H9>0,Debts!$E$13,999),IF(I9>0,Debts!$E$14,999),IF(J9>0,Debts!$E$15,999))),MAX(0,(B10-(MIN(C9+0,C9*(1+Debts!$C$8/12))*0+MIN(C9*(1+Debts!$C$8/12),Debts!$D$8)+MIN(C9+0,D9*(1+Debts!$C$9/12))*0+MIN(D9*(1+Debts!$C$9/12),Debts!$D$9)+MIN(C9+0,E9*(1+Debts!$C$10/12))*0+MIN(E9*(1+Debts!$C$10/12),Debts!$D$10)+MIN(C9+0,F9*(1+Debts!$C$11/12))*0+MIN(F9*(1+Debts!$C$11/12),Debts!$D$11)+MIN(C9+0,G9*(1+Debts!$C$12/12))*0+MIN(G9*(1+Debts!$C$12/12),Debts!$D$12)+MIN(C9+0,H9*(1+Debts!$C$13/12))*0+MIN(H9*(1+Debts!$C$13/12),Debts!$D$13)+MIN(C9+0,I9*(1+Debts!$C$14/12))*0+MIN(I9*(1+Debts!$C$14/12),Debts!$D$14)+MIN(C9+0,J9*(1+Debts!$C$15/12))*0+MIN(J9*(1+Debts!$C$15/12),Debts!$D$15)))),0))) -> 750 | H10: =IF(H9<=0,0,MAX(0,H9*(1+Debts!$C$13/12)-MIN(H9*(1+Debts!$C$13/12),Debts!$D$13)-IF(AND(H9>0,Debts!$E$13=MIN(IF(C9>0,Debts!$E$8,999),IF(D9>0,Debts!$E$9,999),IF(E9>0,Debts!$E$10,999),IF(F9>0,Debts!$E$11,999),IF(G9>0,Debts!$E$12,999),IF(H9>0,Debts!$E$13,999),IF(I9>0,Debts!$E$14,999),IF(J9>0,Debts!$E$15,999))),MAX(0,(B10-(MIN(C9+0,C9*(1+Debts!$C$8/12))*0+MIN(C9*(1+Debts!$C$8/12),Debts!$D$8)+MIN(C9+0,D9*(1+Debts!$C$9/12))*0+MIN(D9*(1+Debts!$C$9/12),Debts!$D$9)+MIN(C9+0,E9*(1+Debts!$C$10/12))*0+MIN(E9*(1+Debts!$C$10/12),Debts!$D$10)+MIN(C9+0,F9*(1+Debts!$C$11/12))*0+MIN(F9*(1+Debts!$C$11/12),Debts!$D$11)+MIN(C9+0,G9*(1+Debts!$C$12/12))*0+MIN(G9*(1+Debts!$C$12/12),Debts!$D$12)+MIN(C9+0,H9*(1+Debts!$C$13/12))*0+MIN(H9*(1+Debts!$C$13/12),Debts!$D$13)+MIN(C9+0,I9*(1+Debts!$C$14/12))*0+MIN(I9*(1+Debts!$C$14/12),Debts!$D$14)+MIN(C9+0,J9*(1+Debts!$C$15/12))*0+MIN(J9*(1+Debts!$C$15/12),Debts!$D$15)))),0))) -> 0 | I10: =IF(I9<=0,0,MAX(0,I9*(1+Debts!$C$14/12)-MIN(I9*(1+Debts!$C$14/12),Debts!$D$14)-IF(AND(I9>0,Debts!$E$14=MIN(IF(C9>0,Debts!$E$8,999),IF(D9>0,Debts!$E$9,999),IF(E9>0,Debts!$E$10,999),IF(F9>0,Debts!$E$11,999),IF(G9>0,Debts!$E$12,999),IF(H9>0,Debts!$E$13,999),IF(I9>0,Debts!$E$14,999),IF(J9>0,Debts!$E$15,999))),MAX(0,(B10-(MIN(C9+0,C9*(1+Debts!$C$8/12))*0+MIN(C9*(1+Debts!$C$8/12),Debts!$D$8)+MIN(C9+0,D9*(1+Debts!$C$9/12))*0+MIN(D9*(1+Debts!$C$9/12),Debts!$D$9)+MIN(C9+0,E9*(1+Debts!$C$10/12))*0+MIN(E9*(1+Debts!$C$10/12),Debts!$D$10)+MIN(C9+0,F9*(1+Debts!$C$11/12))*0+MIN(F9*(1+Debts!$C$11/12),Debts!$D$11)+MIN(C9+0,G9*(1+Debts!$C$12/12))*0+MIN(G9*(1+Debts!$C$12/12),Debts!$D$12)+MIN(C9+0,H9*(1+Debts!$C$13/12))*0+MIN(H9*(1+Debts!$C$13/12),Debts!$D$13)+MIN(C9+0,I9*(1+Debts!$C$14/12))*0+MIN(I9*(1+Debts!$C$14/12),Debts!$D$14)+MIN(C9+0,J9*(1+Debts!$C$15/12))*0+MIN(J9*(1+Debts!$C$15/12),Debts!$D$15)))),0))) -> 0 | J10: =IF(J9<=0,0,MAX(0,J9*(1+Debts!$C$15/12)-MIN(J9*(1+Debts!$C$15/12),Debts!$D$15)-IF(AND(J9>0,Debts!$E$15=MIN(IF(C9>0,Debts!$E$8,999),IF(D9>0,Debts!$E$9,999),IF(E9>0,Debts!$E$10,999),IF(F9>0,Debts!$E$11,999),IF(G9>0,Debts!$E$12,999),IF(H9>0,Debts!$E$13,999),IF(I9>0,Debts!$E$14,999),IF(J9>0,Debts!$E$15,999))),MAX(0,(B10-(MIN(C9+0,C9*(1+Debts!$C$8/12))*0+MIN(C9*(1+Debts!$C$8/12),Debts!$D$8)+MIN(C9+0,D9*(1+Debts!$C$9/12))*0+MIN(D9*(1+Debts!$C$9/12),Debts!$D$9)+MIN(C9+0,E9*(1+Debts!$C$10/12))*0+MIN(E9*(1+Debts!$C$10/12),Debts!$D$10)+MIN(C9+0,F9*(1+Debts!$C$11/12))*0+MIN(F9*(1+Debts!$C$11/12),Debts!$D$11)+MIN(C9+0,G9*(1+Debts!$C$12/12))*0+MIN(G9*(1+Debts!$C$12/12),Debts!$D$12)+MIN(C9+0,H9*(1+Debts!$C$13/12))*0+MIN(H9*(1+Debts!$C$13/12),Debts!$D$13)+MIN(C9+0,I9*(1+Debts!$C$14/12))*0+MIN(I9*(1+Debts!$C$14/12),Debts!$D$14)+MIN(C9+0,J9*(1+Debts!$C$15/12))*0+MIN(J9*(1+Debts!$C$15/12),Debts!$D$15)))),0))) -> 0 | K10: =IF(C9>0,C9*Debts!$C$8/12,0)+IF(D9>0,D9*Debts!$C$9/12,0)+IF(E9>0,E9*Debts!$C$10/12,0)+IF(F9>0,F9*Debts!$C$11/12,0)+IF(G9>0,G9*Debts!$C$12/12,0)+IF(H9>0,H9*Debts!$C$13/12,0)+IF(I9>0,I9*Debts!$C$14/12,0)+IF(J9>0,J9*Debts!$C$15/12,0) -> 302.12228 | L10: =SUM(C10:J10) -> 37140.923
A11: =4 -> 4 | B11: =IF(L10<=0,0,Debts!$D$16+Debts!$B$4) -> 1200 | C11: =IF(C10<=0,0,MAX(0,C10*(1+Debts!$C$8/12)-MIN(C10*(1+Debts!$C$8/12),Debts!$D$8)-IF(AND(C10>0,Debts!$E$8=MIN(IF(C10>0,Debts!$E$8,999),IF(D10>0,Debts!$E$9,999),IF(E10>0,Debts!$E$10,999),IF(F10>0,Debts!$E$11,999),IF(G10>0,Debts!$E$12,999),IF(H10>0,Debts!$E$13,999),IF(I10>0,Debts!$E$14,999),IF(J10>0,Debts!$E$15,999))),MAX(0,(B11-(MIN(C10+0,C10*(1+Debts!$C$8/12))*0+MIN(C10*(1+Debts!$C$8/12),Debts!$D$8)+MIN(C10+0,D10*(1+Debts!$C$9/12))*0+MIN(D10*(1+Debts!$C$9/12),Debts!$D$9)+MIN(C10+0,E10*(1+Debts!$C$10/12))*0+MIN(E10*(1+Debts!$C$10/12),Debts!$D$10)+MIN(C10+0,F10*(1+Debts!$C$11/12))*0+MIN(F10*(1+Debts!$C$11/12),Debts!$D$11)+MIN(C10+0,G10*(1+Debts!$C$12/12))*0+MIN(G10*(1+Debts!$C$12/12),Debts!$D$12)+MIN(C10+0,H10*(1+Debts!$C$13/12))*0+MIN(H10*(1+Debts!$C$13/12),Debts!$D$13)+MIN(C10+0,I10*(1+Debts!$C$14/12))*0+MIN(I10*(1+Debts!$C$14/12),Debts!$D$14)+MIN(C10+0,J10*(1+Debts!$C$15/12))*0+MIN(J10*(1+Debts!$C$15/12),Debts!$D$15)))),0))) -> 4440.7813 | D11: =IF(D10<=0,0,MAX(0,D10*(1+Debts!$C$9/12)-MIN(D10*(1+Debts!$C$9/12),Debts!$D$9)-IF(AND(D10>0,Debts!$E$9=MIN(IF(C10>0,Debts!$E$8,999),IF(D10>0,Debts!$E$9,999),IF(E10>0,Debts!$E$10,999),IF(F10>0,Debts!$E$11,999),IF(G10>0,Debts!$E$12,999),IF(H10>0,Debts!$E$13,999),IF(I10>0,Debts!$E$14,999),IF(J10>0,Debts!$E$15,999))),MAX(0,(B11-(MIN(C10+0,C10*(1+Debts!$C$8/12))*0+MIN(C10*(1+Debts!$C$8/12),Debts!$D$8)+MIN(C10+0,D10*(1+Debts!$C$9/12))*0+MIN(D10*(1+Debts!$C$9/12),Debts!$D$9)+MIN(C10+0,E10*(1+Debts!$C$10/12))*0+MIN(E10*(1+Debts!$C$10/12),Debts!$D$10)+MIN(C10+0,F10*(1+Debts!$C$11/12))*0+MIN(F10*(1+Debts!$C$11/12),Debts!$D$11)+MIN(C10+0,G10*(1+Debts!$C$12/12))*0+MIN(G10*(1+Debts!$C$12/12),Debts!$D$12)+MIN(C10+0,H10*(1+Debts!$C$13/12))*0+MIN(H10*(1+Debts!$C$13/12),Debts!$D$13)+MIN(C10+0,I10*(1+Debts!$C$14/12))*0+MIN(I10*(1+Debts!$C$14/12),Debts!$D$14)+MIN(C10+0,J10*(1+Debts!$C$15/12))*0+MIN(J10*(1+Debts!$C$15/12),Debts!$D$15)))),0))) -> 2271.7418 | E11: =IF(E10<=0,0,MAX(0,E10*(1+Debts!$C$10/12)-MIN(E10*(1+Debts!$C$10/12),Debts!$D$10)-IF(AND(E10>0,Debts!$E$10=MIN(IF(C10>0,Debts!$E$8,999),IF(D10>0,Debts!$E$9,999),IF(E10>0,Debts!$E$10,999),IF(F10>0,Debts!$E$11,999),IF(G10>0,Debts!$E$12,999),IF(H10>0,Debts!$E$13,999),IF(I10>0,Debts!$E$14,999),IF(J10>0,Debts!$E$15,999))),MAX(0,(B11-(MIN(C10+0,C10*(1+Debts!$C$8/12))*0+MIN(C10*(1+Debts!$C$8/12),Debts!$D$8)+MIN(C10+0,D10*(1+Debts!$C$9/12))*0+MIN(D10*(1+Debts!$C$9/12),Debts!$D$9)+MIN(C10+0,E10*(1+Debts!$C$10/12))*0+MIN(E10*(1+Debts!$C$10/12),Debts!$D$10)+MIN(C10+0,F10*(1+Debts!$C$11/12))*0+MIN(F10*(1+Debts!$C$11/12),Debts!$D$11)+MIN(C10+0,G10*(1+Debts!$C$12/12))*0+MIN(G10*(1+Debts!$C$12/12),Debts!$D$12)+MIN(C10+0,H10*(1+Debts!$C$13/12))*0+MIN(H10*(1+Debts!$C$13/12),Debts!$D$13)+MIN(C10+0,I10*(1+Debts!$C$14/12))*0+MIN(I10*(1+Debts!$C$14/12),Debts!$D$14)+MIN(C10+0,J10*(1+Debts!$C$15/12))*0+MIN(J10*(1+Debts!$C$15/12),Debts!$D$15)))),0))) -> 10823.014 | F11: =IF(F10<=0,0,MAX(0,F10*(1+Debts!$C$11/12)-MIN(F10*(1+Debts!$C$11/12),Debts!$D$11)-IF(AND(F10>0,Debts!$E$11=MIN(IF(C10>0,Debts!$E$8,999),IF(D10>0,Debts!$E$9,999),IF(E10>0,Debts!$E$10,999),IF(F10>0,Debts!$E$11,999),IF(G10>0,Debts!$E$12,999),IF(H10>0,Debts!$E$13,999),IF(I10>0,Debts!$E$14,999),IF(J10>0,Debts!$E$15,999))),MAX(0,(B11-(MIN(C10+0,C10*(1+Debts!$C$8/12))*0+MIN(C10*(1+Debts!$C$8/12),Debts!$D$8)+MIN(C10+0,D10*(1+Debts!$C$9/12))*0+MIN(D10*(1+Debts!$C$9/12),Debts!$D$9)+MIN(C10+0,E10*(1+Debts!$C$10/12))*0+MIN(E10*(1+Debts!$C$10/12),Debts!$D$10)+MIN(C10+0,F10*(1+Debts!$C$11/12))*0+MIN(F10*(1+Debts!$C$11/12),Debts!$D$11)+MIN(C10+0,G10*(1+Debts!$C$12/12))*0+MIN(G10*(1+Debts!$C$12/12),Debts!$D$12)+MIN(C10+0,H10*(1+Debts!$C$13/12))*0+MIN(H10*(1+Debts!$C$13/12),Debts!$D$13)+MIN(C10+0,I10*(1+Debts!$C$14/12))*0+MIN(I10*(1+Debts!$C$14/12),Debts!$D$14)+MIN(C10+0,J10*(1+Debts!$C$15/12))*0+MIN(J10*(1+Debts!$C$15/12),Debts!$D$15)))),0))) -> 17995.713 | G11: =IF(G10<=0,0,MAX(0,G10*(1+Debts!$C$12/12)-MIN(G10*(1+Debts!$C$12/12),Debts!$D$12)-IF(AND(G10>0,Debts!$E$12=MIN(IF(C10>0,Debts!$E$8,999),IF(D10>0,Debts!$E$9,999),IF(E10>0,Debts!$E$10,999),IF(F10>0,Debts!$E$11,999),IF(G10>0,Debts!$E$12,999),IF(H10>0,Debts!$E$13,999),IF(I10>0,Debts!$E$14,999),IF(J10>0,Debts!$E$15,999))),MAX(0,(B11-(MIN(C10+0,C10*(1+Debts!$C$8/12))*0+MIN(C10*(1+Debts!$C$8/12),Debts!$D$8)+MIN(C10+0,D10*(1+Debts!$C$9/12))*0+MIN(D10*(1+Debts!$C$9/12),Debts!$D$9)+MIN(C10+0,E10*(1+Debts!$C$10/12))*0+MIN(E10*(1+Debts!$C$10/12),Debts!$D$10)+MIN(C10+0,F10*(1+Debts!$C$11/12))*0+MIN(F10*(1+Debts!$C$11/12),Debts!$D$11)+MIN(C10+0,G10*(1+Debts!$C$12/12))*0+MIN(G10*(1+Debts!$C$12/12),Debts!$D$12)+MIN(C10+0,H10*(1+Debts!$C$13/12))*0+MIN(H10*(1+Debts!$C$13/12),Debts!$D$13)+MIN(C10+0,I10*(1+Debts!$C$14/12))*0+MIN(I10*(1+Debts!$C$14/12),Debts!$D$14)+MIN(C10+0,J10*(1+Debts!$C$15/12))*0+MIN(J10*(1+Debts!$C$15/12),Debts!$D$15)))),0))) -> 700 | H11: =IF(H10<=0,0,MAX(0,H10*(1+Debts!$C$13/12)-MIN(H10*(1+Debts!$C$13/12),Debts!$D$13)-IF(AND(H10>0,Debts!$E$13=MIN(IF(C10>0,Debts!$E$8,999),IF(D10>0,Debts!$E$9,999),IF(E10>0,Debts!$E$10,999),IF(F10>0,Debts!$E$11,999),IF(G10>0,Debts!$E$12,999),IF(H10>0,Debts!$E$13,999),IF(I10>0,Debts!$E$14,999),IF(J10>0,Debts!$E$15,999))),MAX(0,(B11-(MIN(C10+0,C10*(1+Debts!$C$8/12))*0+MIN(C10*(1+Debts!$C$8/12),Debts!$D$8)+MIN(C10+0,D10*(1+Debts!$C$9/12))*0+MIN(D10*(1+Debts!$C$9/12),Debts!$D$9)+MIN(C10+0,E10*(1+Debts!$C$10/12))*0+MIN(E10*(1+Debts!$C$10/12),Debts!$D$10)+MIN(C10+0,F10*(1+Debts!$C$11/12))*0+MIN(F10*(1+Debts!$C$11/12),Debts!$D$11)+MIN(C10+0,G10*(1+Debts!$C$12/12))*0+MIN(G10*(1+Debts!$C$12/12),Debts!$D$12)+MIN(C10+0,H10*(1+Debts!$C$13/12))*0+MIN(H10*(1+Debts!$C$13/12),Debts!$D$13)+MIN(C10+0,I10*(1+Debts!$C$14/12))*0+MIN(I10*(1+Debts!$C$14/12),Debts!$D$14)+MIN(C10+0,J10*(1+Debts!$C$15/12))*0+MIN(J10*(1+Debts!$C$15/12),Debts!$D$15)))),0))) -> 0 | I11: =IF(I10<=0,0,MAX(0,I10*(1+Debts!$C$14/12)-MIN(I10*(1+Debts!$C$14/12),Debts!$D$14)-IF(AND(I10>0,Debts!$E$14=MIN(IF(C10>0,Debts!$E$8,999),IF(D10>0,Debts!$E$9,999),IF(E10>0,Debts!$E$10,999),IF(F10>0,Debts!$E$11,999),IF(G10>0,Debts!$E$12,999),IF(H10>0,Debts!$E$13,999),IF(I10>0,Debts!$E$14,999),IF(J10>0,Debts!$E$15,999))),MAX(0,(B11-(MIN(C10+0,C10*(1+Debts!$C$8/12))*0+MIN(C10*(1+Debts!$C$8/12),Debts!$D$8)+MIN(C10+0,D10*(1+Debts!$C$9/12))*0+MIN(D10*(1+Debts!$C$9/12),Debts!$D$9)+MIN(C10+0,E10*(1+Debts!$C$10/12))*0+MIN(E10*(1+Debts!$C$10/12),Debts!$D$10)+MIN(C10+0,F10*(1+Debts!$C$11/12))*0+MIN(F10*(1+Debts!$C$11/12),Debts!$D$11)+MIN(C10+0,G10*(1+Debts!$C$12/12))*0+MIN(G10*(1+Debts!$C$12/12),Debts!$D$12)+MIN(C10+0,H10*(1+Debts!$C$13/12))*0+MIN(H10*(1+Debts!$C$13/12),Debts!$D$13)+MIN(C10+0,I10*(1+Debts!$C$14/12))*0+MIN(I10*(1+Debts!$C$14/12),Debts!$D$14)+MIN(C10+0,J10*(1+Debts!$C$15/12))*0+MIN(J10*(1+Debts!$C$15/12),Debts!$D$15)))),0))) -> 0 | J11: =IF(J10<=0,0,MAX(0,J10*(1+Debts!$C$15/12)-MIN(J10*(1+Debts!$C$15/12),Debts!$D$15)-IF(AND(J10>0,Debts!$E$15=MIN(IF(C10>0,Debts!$E$8,999),IF(D10>0,Debts!$E$9,999),IF(E10>0,Debts!$E$10,999),IF(F10>0,Debts!$E$11,999),IF(G10>0,Debts!$E$12,999),IF(H10>0,Debts!$E$13,999),IF(I10>0,Debts!$E$14,999),IF(J10>0,Debts!$E$15,999))),MAX(0,(B11-(MIN(C10+0,C10*(1+Debts!$C$8/12))*0+MIN(C10*(1+Debts!$C$8/12),Debts!$D$8)+MIN(C10+0,D10*(1+Debts!$C$9/12))*0+MIN(D10*(1+Debts!$C$9/12),Debts!$D$9)+MIN(C10+0,E10*(1+Debts!$C$10/12))*0+MIN(E10*(1+Debts!$C$10/12),Debts!$D$10)+MIN(C10+0,F10*(1+Debts!$C$11/12))*0+MIN(F10*(1+Debts!$C$11/12),Debts!$D$11)+MIN(C10+0,G10*(1+Debts!$C$12/12))*0+MIN(G10*(1+Debts!$C$12/12),Debts!$D$12)+MIN(C10+0,H10*(1+Debts!$C$13/12))*0+MIN(H10*(1+Debts!$C$13/12),Debts!$D$13)+MIN(C10+0,I10*(1+Debts!$C$14/12))*0+MIN(I10*(1+Debts!$C$14/12),Debts!$D$14)+MIN(C10+0,J10*(1+Debts!$C$15/12))*0+MIN(J10*(1+Debts!$C$15/12),Debts!$D$15)))),0))) -> 0 | K11: =IF(C10>0,C10*Debts!$C$8/12,0)+IF(D10>0,D10*Debts!$C$9/12,0)+IF(E10>0,E10*Debts!$C$10/12,0)+IF(F10>0,F10*Debts!$C$11/12,0)+IF(G10>0,G10*Debts!$C$12/12,0)+IF(H10>0,H10*Debts!$C$13/12,0)+IF(I10>0,I10*Debts!$C$14/12,0)+IF(J10>0,J10*Debts!$C$15/12,0) -> 290.32663 | L11: =SUM(C11:J11) -> 36231.25
A12: =5 -> 5 | B12: =IF(L11<=0,0,Debts!$D$16+Debts!$B$4) -> 1200 | C12: =IF(C11<=0,0,MAX(0,C11*(1+Debts!$C$8/12)-MIN(C11*(1+Debts!$C$8/12),Debts!$D$8)-IF(AND(C11>0,Debts!$E$8=MIN(IF(C11>0,Debts!$E$8,999),IF(D11>0,Debts!$E$9,999),IF(E11>0,Debts!$E$10,999),IF(F11>0,Debts!$E$11,999),IF(G11>0,Debts!$E$12,999),IF(H11>0,Debts!$E$13,999),IF(I11>0,Debts!$E$14,999),IF(J11>0,Debts!$E$15,999))),MAX(0,(B12-(MIN(C11+0,C11*(1+Debts!$C$8/12))*0+MIN(C11*(1+Debts!$C$8/12),Debts!$D$8)+MIN(C11+0,D11*(1+Debts!$C$9/12))*0+MIN(D11*(1+Debts!$C$9/12),Debts!$D$9)+MIN(C11+0,E11*(1+Debts!$C$10/12))*0+MIN(E11*(1+Debts!$C$10/12),Debts!$D$10)+MIN(C11+0,F11*(1+Debts!$C$11/12))*0+MIN(F11*(1+Debts!$C$11/12),Debts!$D$11)+MIN(C11+0,G11*(1+Debts!$C$12/12))*0+MIN(G11*(1+Debts!$C$12/12),Debts!$D$12)+MIN(C11+0,H11*(1+Debts!$C$13/12))*0+MIN(H11*(1+Debts!$C$13/12),Debts!$D$13)+MIN(C11+0,I11*(1+Debts!$C$14/12))*0+MIN(I11*(1+Debts!$C$14/12),Debts!$D$14)+MIN(C11+0,J11*(1+Debts!$C$15/12))*0+MIN(J11*(1+Debts!$C$15/12),Debts!$D$15)))),0))) -> 3977.9275 | D12: =IF(D11<=0,0,MAX(0,D11*(1+Debts!$C$9/12)-MIN(D11*(1+Debts!$C$9/12),Debts!$D$9)-IF(AND(D11>0,Debts!$E$9=MIN(IF(C11>0,Debts!$E$8,999),IF(D11>0,Debts!$E$9,999),IF(E11>0,Debts!$E$10,999),IF(F11>0,Debts!$E$11,999),IF(G11>0,Debts!$E$12,999),IF(H11>0,Debts!$E$13,999),IF(I11>0,Debts!$E$14,999),IF(J11>0,Debts!$E$15,999))),MAX(0,(B12-(MIN(C11+0,C11*(1+Debts!$C$8/12))*0+MIN(C11*(1+Debts!$C$8/12),Debts!$D$8)+MIN(C11+0,D11*(1+Debts!$C$9/12))*0+MIN(D11*(1+Debts!$C$9/12),Debts!$D$9)+MIN(C11+0,E11*(1+Debts!$C$10/12))*0+MIN(E11*(1+Debts!$C$10/12),Debts!$D$10)+MIN(C11+0,F11*(1+Debts!$C$11/12))*0+MIN(F11*(1+Debts!$C$11/12),Debts!$D$11)+MIN(C11+0,G11*(1+Debts!$C$12/12))*0+MIN(G11*(1+Debts!$C$12/12),Debts!$D$12)+MIN(C11+0,H11*(1+Debts!$C$13/12))*0+MIN(H11*(1+Debts!$C$13/12),Debts!$D$13)+MIN(C11+0,I11*(1+Debts!$C$14/12))*0+MIN(I11*(1+Debts!$C$14/12),Debts!$D$14)+MIN(C11+0,J11*(1+Debts!$C$15/12))*0+MIN(J11*(1+Debts!$C$15/12),Debts!$D$15)))),0))) -> 2238.2011 | E12: =IF(E11<=0,0,MAX(0,E11*(1+Debts!$C$10/12)-MIN(E11*(1+Debts!$C$10/12),Debts!$D$10)-IF(AND(E11>0,Debts!$E$10=MIN(IF(C11>0,Debts!$E$8,999),IF(D11>0,Debts!$E$9,999),IF(E11>0,Debts!$E$10,999),IF(F11>0,Debts!$E$11,999),IF(G11>0,Debts!$E$12,999),IF(H11>0,Debts!$E$13,999),IF(I11>0,Debts!$E$14,999),IF(J11>0,Debts!$E$15,999))),MAX(0,(B12-(MIN(C11+0,C11*(1+Debts!$C$8/12))*0+MIN(C11*(1+Debts!$C$8/12),Debts!$D$8)+MIN(C11+0,D11*(1+Debts!$C$9/12))*0+MIN(D11*(1+Debts!$C$9/12),Debts!$D$9)+MIN(C11+0,E11*(1+Debts!$C$10/12))*0+MIN(E11*(1+Debts!$C$10/12),Debts!$D$10)+MIN(C11+0,F11*(1+Debts!$C$11/12))*0+MIN(F11*(1+Debts!$C$11/12),Debts!$D$11)+MIN(C11+0,G11*(1+Debts!$C$12/12))*0+MIN(G11*(1+Debts!$C$12/12),Debts!$D$12)+MIN(C11+0,H11*(1+Debts!$C$13/12))*0+MIN(H11*(1+Debts!$C$13/12),Debts!$D$13)+MIN(C11+0,I11*(1+Debts!$C$14/12))*0+MIN(I11*(1+Debts!$C$14/12),Debts!$D$14)+MIN(C11+0,J11*(1+Debts!$C$15/12))*0+MIN(J11*(1+Debts!$C$15/12),Debts!$D$15)))),0))) -> 10575.246 | F12: =IF(F11<=0,0,MAX(0,F11*(1+Debts!$C$11/12)-MIN(F11*(1+Debts!$C$11/12),Debts!$D$11)-IF(AND(F11>0,Debts!$E$11=MIN(IF(C11>0,Debts!$E$8,999),IF(D11>0,Debts!$E$9,999),IF(E11>0,Debts!$E$10,999),IF(F11>0,Debts!$E$11,999),IF(G11>0,Debts!$E$12,999),IF(H11>0,Debts!$E$13,999),IF(I11>0,Debts!$E$14,999),IF(J11>0,Debts!$E$15,999))),MAX(0,(B12-(MIN(C11+0,C11*(1+Debts!$C$8/12))*0+MIN(C11*(1+Debts!$C$8/12),Debts!$D$8)+MIN(C11+0,D11*(1+Debts!$C$9/12))*0+MIN(D11*(1+Debts!$C$9/12),Debts!$D$9)+MIN(C11+0,E11*(1+Debts!$C$10/12))*0+MIN(E11*(1+Debts!$C$10/12),Debts!$D$10)+MIN(C11+0,F11*(1+Debts!$C$11/12))*0+MIN(F11*(1+Debts!$C$11/12),Debts!$D$11)+MIN(C11+0,G11*(1+Debts!$C$12/12))*0+MIN(G11*(1+Debts!$C$12/12),Debts!$D$12)+MIN(C11+0,H11*(1+Debts!$C$13/12))*0+MIN(H11*(1+Debts!$C$13/12),Debts!$D$13)+MIN(C11+0,I11*(1+Debts!$C$14/12))*0+MIN(I11*(1+Debts!$C$14/12),Debts!$D$14)+MIN(C11+0,J11*(1+Debts!$C$15/12))*0+MIN(J11*(1+Debts!$C$15/12),Debts!$D$15)))),0))) -> 17868.193 | G12: =IF(G11<=0,0,MAX(0,G11*(1+Debts!$C$12/12)-MIN(G11*(1+Debts!$C$12/12),Debts!$D$12)-IF(AND(G11>0,Debts!$E$12=MIN(IF(C11>0,Debts!$E$8,999),IF(D11>0,Debts!$E$9,999),IF(E11>0,Debts!$E$10,999),IF(F11>0,Debts!$E$11,999),IF(G11>0,Debts!$E$12,999),IF(H11>0,Debts!$E$13,999),IF(I11>0,Debts!$E$14,999),IF(J11>0,Debts!$E$15,999))),MAX(0,(B12-(MIN(C11+0,C11*(1+Debts!$C$8/12))*0+MIN(C11*(1+Debts!$C$8/12),Debts!$D$8)+MIN(C11+0,D11*(1+Debts!$C$9/12))*0+MIN(D11*(1+Debts!$C$9/12),Debts!$D$9)+MIN(C11+0,E11*(1+Debts!$C$10/12))*0+MIN(E11*(1+Debts!$C$10/12),Debts!$D$10)+MIN(C11+0,F11*(1+Debts!$C$11/12))*0+MIN(F11*(1+Debts!$C$11/12),Debts!$D$11)+MIN(C11+0,G11*(1+Debts!$C$12/12))*0+MIN(G11*(1+Debts!$C$12/12),Debts!$D$12)+MIN(C11+0,H11*(1+Debts!$C$13/12))*0+MIN(H11*(1+Debts!$C$13/12),Debts!$D$13)+MIN(C11+0,I11*(1+Debts!$C$14/12))*0+MIN(I11*(1+Debts!$C$14/12),Debts!$D$14)+MIN(C11+0,J11*(1+Debts!$C$15/12))*0+MIN(J11*(1+Debts!$C$15/12),Debts!$D$15)))),0))) -> 650 | H12: =IF(H11<=0,0,MAX(0,H11*(1+Debts!$C$13/12)-MIN(H11*(1+Debts!$C$13/12),Debts!$D$13)-IF(AND(H11>0,Debts!$E$13=MIN(IF(C11>0,Debts!$E$8,999),IF(D11>0,Debts!$E$9,999),IF(E11>0,Debts!$E$10,999),IF(F11>0,Debts!$E$11,999),IF(G11>0,Debts!$E$12,999),IF(H11>0,Debts!$E$13,999),IF(I11>0,Debts!$E$14,999),IF(J11>0,Debts!$E$15,999))),MAX(0,(B12-(MIN(C11+0,C11*(1+Debts!$C$8/12))*0+MIN(C11*(1+Debts!$C$8/12),Debts!$D$8)+MIN(C11+0,D11*(1+Debts!$C$9/12))*0+MIN(D11*(1+Debts!$C$9/12),Debts!$D$9)+MIN(C11+0,E11*(1+Debts!$C$10/12))*0+MIN(E11*(1+Debts!$C$10/12),Debts!$D$10)+MIN(C11+0,F11*(1+Debts!$C$11/12))*0+MIN(F11*(1+Debts!$C$11/12),Debts!$D$11)+MIN(C11+0,G11*(1+Debts!$C$12/12))*0+MIN(G11*(1+Debts!$C$12/12),Debts!$D$12)+MIN(C11+0,H11*(1+Debts!$C$13/12))*0+MIN(H11*(1+Debts!$C$13/12),Debts!$D$13)+MIN(C11+0,I11*(1+Debts!$C$14/12))*0+MIN(I11*(1+Debts!$C$14/12),Debts!$D$14)+MIN(C11+0,J11*(1+Debts!$C$15/12))*0+MIN(J11*(1+Debts!$C$15/12),Debts!$D$15)))),0))) -> 0 | I12: =IF(I11<=0,0,MAX(0,I11*(1+Debts!$C$14/12)-MIN(I11*(1+Debts!$C$14/12),Debts!$D$14)-IF(AND(I11>0,Debts!$E$14=MIN(IF(C11>0,Debts!$E$8,999),IF(D11>0,Debts!$E$9,999),IF(E11>0,Debts!$E$10,999),IF(F11>0,Debts!$E$11,999),IF(G11>0,Debts!$E$12,999),IF(H11>0,Debts!$E$13,999),IF(I11>0,Debts!$E$14,999),IF(J11>0,Debts!$E$15,999))),MAX(0,(B12-(MIN(C11+0,C11*(1+Debts!$C$8/12))*0+MIN(C11*(1+Debts!$C$8/12),Debts!$D$8)+MIN(C11+0,D11*(1+Debts!$C$9/12))*0+MIN(D11*(1+Debts!$C$9/12),Debts!$D$9)+MIN(C11+0,E11*(1+Debts!$C$10/12))*0+MIN(E11*(1+Debts!$C$10/12),Debts!$D$10)+MIN(C11+0,F11*(1+Debts!$C$11/12))*0+MIN(F11*(1+Debts!$C$11/12),Debts!$D$11)+MIN(C11+0,G11*(1+Debts!$C$12/12))*0+MIN(G11*(1+Debts!$C$12/12),Debts!$D$12)+MIN(C11+0,H11*(1+Debts!$C$13/12))*0+MIN(H11*(1+Debts!$C$13/12),Debts!$D$13)+MIN(C11+0,I11*(1+Debts!$C$14/12))*0+MIN(I11*(1+Debts!$C$14/12),Debts!$D$14)+MIN(C11+0,J11*(1+Debts!$C$15/12))*0+MIN(J11*(1+Debts!$C$15/12),Debts!$D$15)))),0))) -> 0 | J12: =IF(J11<=0,0,MAX(0,J11*(1+Debts!$C$15/12)-MIN(J11*(1+Debts!$C$15/12),Debts!$D$15)-IF(AND(J11>0,Debts!$E$15=MIN(IF(C11>0,Debts!$E$8,999),IF(D11>0,Debts!$E$9,999),IF(E11>0,Debts!$E$10,999),IF(F11>0,Debts!$E$11,999),IF(G11>0,Debts!$E$12,999),IF(H11>0,Debts!$E$13,999),IF(I11>0,Debts!$E$14,999),IF(J11>0,Debts!$E$15,999))),MAX(0,(B12-(MIN(C11+0,C11*(1+Debts!$C$8/12))*0+MIN(C11*(1+Debts!$C$8/12),Debts!$D$8)+MIN(C11+0,D11*(1+Debts!$C$9/12))*0+MIN(D11*(1+Debts!$C$9/12),Debts!$D$9)+MIN(C11+0,E11*(1+Debts!$C$10/12))*0+MIN(E11*(1+Debts!$C$10/12),Debts!$D$10)+MIN(C11+0,F11*(1+Debts!$C$11/12))*0+MIN(F11*(1+Debts!$C$11/12),Debts!$D$11)+MIN(C11+0,G11*(1+Debts!$C$12/12))*0+MIN(G11*(1+Debts!$C$12/12),Debts!$D$12)+MIN(C11+0,H11*(1+Debts!$C$13/12))*0+MIN(H11*(1+Debts!$C$13/12),Debts!$D$13)+MIN(C11+0,I11*(1+Debts!$C$14/12))*0+MIN(I11*(1+Debts!$C$14/12),Debts!$D$14)+MIN(C11+0,J11*(1+Debts!$C$15/12))*0+MIN(J11*(1+Debts!$C$15/12),Debts!$D$15)))),0))) -> 0 | K12: =IF(C11>0,C11*Debts!$C$8/12,0)+IF(D11>0,D11*Debts!$C$9/12,0)+IF(E11>0,E11*Debts!$C$10/12,0)+IF(F11>0,F11*Debts!$C$11/12,0)+IF(G11>0,G11*Debts!$C$12/12,0)+IF(H11>0,H11*Debts!$C$13/12,0)+IF(I11>0,I11*Debts!$C$14/12,0)+IF(J11>0,J11*Debts!$C$15/12,0) -> 278.31818 | L12: =SUM(C12:J12) -> 35309.568
A13: =6 -> 6 | B13: =IF(L12<=0,0,Debts!$D$16+Debts!$B$4) -> 1200 | C13: =IF(C12<=0,0,MAX(0,C12*(1+Debts!$C$8/12)-MIN(C12*(1+Debts!$C$8/12),Debts!$D$8)-IF(AND(C12>0,Debts!$E$8=MIN(IF(C12>0,Debts!$E$8,999),IF(D12>0,Debts!$E$9,999),IF(E12>0,Debts!$E$10,999),IF(F12>0,Debts!$E$11,999),IF(G12>0,Debts!$E$12,999),IF(H12>0,Debts!$E$13,999),IF(I12>0,Debts!$E$14,999),IF(J12>0,Debts!$E$15,999))),MAX(0,(B13-(MIN(C12+0,C12*(1+Debts!$C$8/12))*0+MIN(C12*(1+Debts!$C$8/12),Debts!$D$8)+MIN(C12+0,D12*(1+Debts!$C$9/12))*0+MIN(D12*(1+Debts!$C$9/12),Debts!$D$9)+MIN(C12+0,E12*(1+Debts!$C$10/12))*0+MIN(E12*(1+Debts!$C$10/12),Debts!$D$10)+MIN(C12+0,F12*(1+Debts!$C$11/12))*0+MIN(F12*(1+Debts!$C$11/12),Debts!$D$11)+MIN(C12+0,G12*(1+Debts!$C$12/12))*0+MIN(G12*(1+Debts!$C$12/12),Debts!$D$12)+MIN(C12+0,H12*(1+Debts!$C$13/12))*0+MIN(H12*(1+Debts!$C$13/12),Debts!$D$13)+MIN(C12+0,I12*(1+Debts!$C$14/12))*0+MIN(I12*(1+Debts!$C$14/12),Debts!$D$14)+MIN(C12+0,J12*(1+Debts!$C$15/12))*0+MIN(J12*(1+Debts!$C$15/12),Debts!$D$15)))),0))) -> 3505.4695 | D13: =IF(D12<=0,0,MAX(0,D12*(1+Debts!$C$9/12)-MIN(D12*(1+Debts!$C$9/12),Debts!$D$9)-IF(AND(D12>0,Debts!$E$9=MIN(IF(C12>0,Debts!$E$8,999),IF(D12>0,Debts!$E$9,999),IF(E12>0,Debts!$E$10,999),IF(F12>0,Debts!$E$11,999),IF(G12>0,Debts!$E$12,999),IF(H12>0,Debts!$E$13,999),IF(I12>0,Debts!$E$14,999),IF(J12>0,Debts!$E$15,999))),MAX(0,(B13-(MIN(C12+0,C12*(1+Debts!$C$8/12))*0+MIN(C12*(1+Debts!$C$8/12),Debts!$D$8)+MIN(C12+0,D12*(1+Debts!$C$9/12))*0+MIN(D12*(1+Debts!$C$9/12),Debts!$D$9)+MIN(C12+0,E12*(1+Debts!$C$10/12))*0+MIN(E12*(1+Debts!$C$10/12),Debts!$D$10)+MIN(C12+0,F12*(1+Debts!$C$11/12))*0+MIN(F12*(1+Debts!$C$11/12),Debts!$D$11)+MIN(C12+0,G12*(1+Debts!$C$12/12))*0+MIN(G12*(1+Debts!$C$12/12),Debts!$D$12)+MIN(C12+0,H12*(1+Debts!$C$13/12))*0+MIN(H12*(1+Debts!$C$13/12),Debts!$D$13)+MIN(C12+0,I12*(1+Debts!$C$14/12))*0+MIN(I12*(1+Debts!$C$14/12),Debts!$D$14)+MIN(C12+0,J12*(1+Debts!$C$15/12))*0+MIN(J12*(1+Debts!$C$15/12),Debts!$D$15)))),0))) -> 2204.0483 | E13: =IF(E12<=0,0,MAX(0,E12*(1+Debts!$C$10/12)-MIN(E12*(1+Debts!$C$10/12),Debts!$D$10)-IF(AND(E12>0,Debts!$E$10=MIN(IF(C12>0,Debts!$E$8,999),IF(D12>0,Debts!$E$9,999),IF(E12>0,Debts!$E$10,999),IF(F12>0,Debts!$E$11,999),IF(G12>0,Debts!$E$12,999),IF(H12>0,Debts!$E$13,999),IF(I12>0,Debts!$E$14,999),IF(J12>0,Debts!$E$15,999))),MAX(0,(B13-(MIN(C12+0,C12*(1+Debts!$C$8/12))*0+MIN(C12*(1+Debts!$C$8/12),Debts!$D$8)+MIN(C12+0,D12*(1+Debts!$C$9/12))*0+MIN(D12*(1+Debts!$C$9/12),Debts!$D$9)+MIN(C12+0,E12*(1+Debts!$C$10/12))*0+MIN(E12*(1+Debts!$C$10/12),Debts!$D$10)+MIN(C12+0,F12*(1+Debts!$C$11/12))*0+MIN(F12*(1+Debts!$C$11/12),Debts!$D$11)+MIN(C12+0,G12*(1+Debts!$C$12/12))*0+MIN(G12*(1+Debts!$C$12/12),Debts!$D$12)+MIN(C12+0,H12*(1+Debts!$C$13/12))*0+MIN(H12*(1+Debts!$C$13/12),Debts!$D$13)+MIN(C12+0,I12*(1+Debts!$C$14/12))*0+MIN(I12*(1+Debts!$C$14/12),Debts!$D$14)+MIN(C12+0,J12*(1+Debts!$C$15/12))*0+MIN(J12*(1+Debts!$C$15/12),Debts!$D$15)))),0))) -> 10326.054 | F13: =IF(F12<=0,0,MAX(0,F12*(1+Debts!$C$11/12)-MIN(F12*(1+Debts!$C$11/12),Debts!$D$11)-IF(AND(F12>0,Debts!$E$11=MIN(IF(C12>0,Debts!$E$8,999),IF(D12>0,Debts!$E$9,999),IF(E12>0,Debts!$E$10,999),IF(F12>0,Debts!$E$11,999),IF(G12>0,Debts!$E$12,999),IF(H12>0,Debts!$E$13,999),IF(I12>0,Debts!$E$14,999),IF(J12>0,Debts!$E$15,999))),MAX(0,(B13-(MIN(C12+0,C12*(1+Debts!$C$8/12))*0+MIN(C12*(1+Debts!$C$8/12),Debts!$D$8)+MIN(C12+0,D12*(1+Debts!$C$9/12))*0+MIN(D12*(1+Debts!$C$9/12),Debts!$D$9)+MIN(C12+0,E12*(1+Debts!$C$10/12))*0+MIN(E12*(1+Debts!$C$10/12),Debts!$D$10)+MIN(C12+0,F12*(1+Debts!$C$11/12))*0+MIN(F12*(1+Debts!$C$11/12),Debts!$D$11)+MIN(C12+0,G12*(1+Debts!$C$12/12))*0+MIN(G12*(1+Debts!$C$12/12),Debts!$D$12)+MIN(C12+0,H12*(1+Debts!$C$13/12))*0+MIN(H12*(1+Debts!$C$13/12),Debts!$D$13)+MIN(C12+0,I12*(1+Debts!$C$14/12))*0+MIN(I12*(1+Debts!$C$14/12),Debts!$D$14)+MIN(C12+0,J12*(1+Debts!$C$15/12))*0+MIN(J12*(1+Debts!$C$15/12),Debts!$D$15)))),0))) -> 17740.089 | G13: =IF(G12<=0,0,MAX(0,G12*(1+Debts!$C$12/12)-MIN(G12*(1+Debts!$C$12/12),Debts!$D$12)-IF(AND(G12>0,Debts!$E$12=MIN(IF(C12>0,Debts!$E$8,999),IF(D12>0,Debts!$E$9,999),IF(E12>0,Debts!$E$10,999),IF(F12>0,Debts!$E$11,999),IF(G12>0,Debts!$E$12,999),IF(H12>0,Debts!$E$13,999),IF(I12>0,Debts!$E$14,999),IF(J12>0,Debts!$E$15,999))),MAX(0,(B13-(MIN(C12+0,C12*(1+Debts!$C$8/12))*0+MIN(C12*(1+Debts!$C$8/12),Debts!$D$8)+MIN(C12+0,D12*(1+Debts!$C$9/12))*0+MIN(D12*(1+Debts!$C$9/12),Debts!$D$9)+MIN(C12+0,E12*(1+Debts!$C$10/12))*0+MIN(E12*(1+Debts!$C$10/12),Debts!$D$10)+MIN(C12+0,F12*(1+Debts!$C$11/12))*0+MIN(F12*(1+Debts!$C$11/12),Debts!$D$11)+MIN(C12+0,G12*(1+Debts!$C$12/12))*0+MIN(G12*(1+Debts!$C$12/12),Debts!$D$12)+MIN(C12+0,H12*(1+Debts!$C$13/12))*0+MIN(H12*(1+Debts!$C$13/12),Debts!$D$13)+MIN(C12+0,I12*(1+Debts!$C$14/12))*0+MIN(I12*(1+Debts!$C$14/12),Debts!$D$14)+MIN(C12+0,J12*(1+Debts!$C$15/12))*0+MIN(J12*(1+Debts!$C$15/12),Debts!$D$15)))),0))) -> 600 | H13: =IF(H12<=0,0,MAX(0,H12*(1+Debts!$C$13/12)-MIN(H12*(1+Debts!$C$13/12),Debts!$D$13)-IF(AND(H12>0,Debts!$E$13=MIN(IF(C12>0,Debts!$E$8,999),IF(D12>0,Debts!$E$9,999),IF(E12>0,Debts!$E$10,999),IF(F12>0,Debts!$E$11,999),IF(G12>0,Debts!$E$12,999),IF(H12>0,Debts!$E$13,999),IF(I12>0,Debts!$E$14,999),IF(J12>0,Debts!$E$15,999))),MAX(0,(B13-(MIN(C12+0,C12*(1+Debts!$C$8/12))*0+MIN(C12*(1+Debts!$C$8/12),Debts!$D$8)+MIN(C12+0,D12*(1+Debts!$C$9/12))*0+MIN(D12*(1+Debts!$C$9/12),Debts!$D$9)+MIN(C12+0,E12*(1+Debts!$C$10/12))*0+MIN(E12*(1+Debts!$C$10/12),Debts!$D$10)+MIN(C12+0,F12*(1+Debts!$C$11/12))*0+MIN(F12*(1+Debts!$C$11/12),Debts!$D$11)+MIN(C12+0,G12*(1+Debts!$C$12/12))*0+MIN(G12*(1+Debts!$C$12/12),Debts!$D$12)+MIN(C12+0,H12*(1+Debts!$C$13/12))*0+MIN(H12*(1+Debts!$C$13/12),Debts!$D$13)+MIN(C12+0,I12*(1+Debts!$C$14/12))*0+MIN(I12*(1+Debts!$C$14/12),Debts!$D$14)+MIN(C12+0,J12*(1+Debts!$C$15/12))*0+MIN(J12*(1+Debts!$C$15/12),Debts!$D$15)))),0))) -> 0 | I13: =IF(I12<=0,0,MAX(0,I12*(1+Debts!$C$14/12)-MIN(I12*(1+Debts!$C$14/12),Debts!$D$14)-IF(AND(I12>0,Debts!$E$14=MIN(IF(C12>0,Debts!$E$8,999),IF(D12>0,Debts!$E$9,999),IF(E12>0,Debts!$E$10,999),IF(F12>0,Debts!$E$11,999),IF(G12>0,Debts!$E$12,999),IF(H12>0,Debts!$E$13,999),IF(I12>0,Debts!$E$14,999),IF(J12>0,Debts!$E$15,999))),MAX(0,(B13-(MIN(C12+0,C12*(1+Debts!$C$8/12))*0+MIN(C12*(1+Debts!$C$8/12),Debts!$D$8)+MIN(C12+0,D12*(1+Debts!$C$9/12))*0+MIN(D12*(1+Debts!$C$9/12),Debts!$D$9)+MIN(C12+0,E12*(1+Debts!$C$10/12))*0+MIN(E12*(1+Debts!$C$10/12),Debts!$D$10)+MIN(C12+0,F12*(1+Debts!$C$11/12))*0+MIN(F12*(1+Debts!$C$11/12),Debts!$D$11)+MIN(C12+0,G12*(1+Debts!$C$12/12))*0+MIN(G12*(1+Debts!$C$12/12),Debts!$D$12)+MIN(C12+0,H12*(1+Debts!$C$13/12))*0+MIN(H12*(1+Debts!$C$13/12),Debts!$D$13)+MIN(C12+0,I12*(1+Debts!$C$14/12))*0+MIN(I12*(1+Debts!$C$14/12),Debts!$D$14)+MIN(C12+0,J12*(1+Debts!$C$15/12))*0+MIN(J12*(1+Debts!$C$15/12),Debts!$D$15)))),0))) -> 0 | J13: =IF(J12<=0,0,MAX(0,J12*(1+Debts!$C$15/12)-MIN(J12*(1+Debts!$C$15/12),Debts!$D$15)-IF(AND(J12>0,Debts!$E$15=MIN(IF(C12>0,Debts!$E$8,999),IF(D12>0,Debts!$E$9,999),IF(E12>0,Debts!$E$10,999),IF(F12>0,Debts!$E$11,999),IF(G12>0,Debts!$E$12,999),IF(H12>0,Debts!$E$13,999),IF(I12>0,Debts!$E$14,999),IF(J12>0,Debts!$E$15,999))),MAX(0,(B13-(MIN(C12+0,C12*(1+Debts!$C$8/12))*0+MIN(C12*(1+Debts!$C$8/12),Debts!$D$8)+MIN(C12+0,D12*(1+Debts!$C$9/12))*0+MIN(D12*(1+Debts!$C$9/12),Debts!$D$9)+MIN(C12+0,E12*(1+Debts!$C$10/12))*0+MIN(E12*(1+Debts!$C$10/12),Debts!$D$10)+MIN(C12+0,F12*(1+Debts!$C$11/12))*0+MIN(F12*(1+Debts!$C$11/12),Debts!$D$11)+MIN(C12+0,G12*(1+Debts!$C$12/12))*0+MIN(G12*(1+Debts!$C$12/12),Debts!$D$12)+MIN(C12+0,H12*(1+Debts!$C$13/12))*0+MIN(H12*(1+Debts!$C$13/12),Debts!$D$13)+MIN(C12+0,I12*(1+Debts!$C$14/12))*0+MIN(I12*(1+Debts!$C$14/12),Debts!$D$14)+MIN(C12+0,J12*(1+Debts!$C$15/12))*0+MIN(J12*(1+Debts!$C$15/12),Debts!$D$15)))),0))) -> 0 | K13: =IF(C12>0,C12*Debts!$C$8/12,0)+IF(D12>0,D12*Debts!$C$9/12,0)+IF(E12>0,E12*Debts!$C$10/12,0)+IF(F12>0,F12*Debts!$C$11/12,0)+IF(G12>0,G12*Debts!$C$12/12,0)+IF(H12>0,H12*Debts!$C$13/12,0)+IF(I12>0,I12*Debts!$C$14/12,0)+IF(J12>0,J12*Debts!$C$15/12,0) -> 266.09272 | L13: =SUM(C13:J13) -> 34375.661
