Workbook

Sheet Start Here
A1: Etsy Seller Bookkeeping & Profit Tracker
A2: Simple Sheets Co. — Excel + Google Sheets
A4: Setup
A5: 1. Sales tab: one row per order (or paste your Etsy CSV). Etsy fees calculate from the fee rates on the Settings tab.
A6: 2. Expenses tab: supplies, shipping, ads, software, and any other cost.
A7: 3. Profit tab: monthly revenue, fees, expenses, net profit, and margin, plus a year total for tax time.
A9: Conventions
A10: • Yellow cells with blue text are inputs. Type over the sample numbers.
A11: • Black text is a formula. Leave it alone unless you know what you're changing.
A12: • Green text pulls from another tab.
A13: • Works in Excel 2016+ and Google Sheets (File > Import > Upload > Replace). No macros.
A14: • Fee rates are set to Etsy's published US rates as of 2026 (6.5% transaction, 3% + $0.25 payment processing, $0.20 listing). Update on Settings if they change.
A16: For planning and educational use only. Not financial, legal, or tax advice. Every number is an estimate you should verify for your own business.

Sheet Dashboard
B2: Shop Dashboard
B3: Sales, fees and profit for the year.
B5: ORDERS (YTD) | E5: GROSS SALES | H5: ETSY FEES | K5: NET PROFIT
B6: =Profit!B16 -> 60 | E6: =Profit!C16 -> 513 | H6: =Profit!D16 -> 84.1623 | K6: =Profit!G16 -> 198.8377
B9: PROFIT MARGIN | E9: FEES AS % OF SALES | H9: SET ASIDE FOR TAX | K9: AVG ORDER VALUE
B10: =Profit!H16 -> 0.38759786 | E10: =IF(Profit!C16=0,0,Profit!D16/Profit!C16) -> 0.16405906 | H10: =Profit!I16 -> 68.459425 | K10: =IF(Profit!B16=0,0,Profit!C16/Profit!B16) -> 8.55

Sheet Profit
A1: Monthly Profit
A3: Month | B3: Orders | C3: Gross sales | D3: Etsy fees | E3: Net payout | F3: Expenses | G3: Net profit | H3: Margin | I3: Tax set-aside
A4: 2026-01 | B4: =COUNTIF(Sales!$O$6:$O$265,A4) -> 0 | C4: =SUMIF(Sales!$O$6:$O$265,A4,Sales!$H$6:$H$265) -> 0 | D4: =SUMIF(Sales!$O$6:$O$265,A4,Sales!$I$6:$I$265)+SUMIF(Sales!$O$6:$O$265,A4,Sales!$J$6:$J$265)+SUMIF(Sales!$O$6:$O$265,A4,Sales!$K$6:$K$265)+SUMIF(Sales!$O$6:$O$265,A4,Sales!$M$6:$M$265) -> 0 | E4: =C4-D4 -> 0 | F4: =SUMIF(Expenses!$E$5:$E$111,A4,Expenses!$D$5:$D$111) -> 0 | G4: =E4-F4 -> 0 | H4: =IF(C4=0,0,G4/C4) -> 0 | I4: =MAX(0,G4)*Settings!$B$10 -> 0
A5: 2026-02 | B5: =COUNTIF(Sales!$O$6:$O$265,A5) -> 0 | C5: =SUMIF(Sales!$O$6:$O$265,A5,Sales!$H$6:$H$265) -> 0 | D5: =SUMIF(Sales!$O$6:$O$265,A5,Sales!$I$6:$I$265)+SUMIF(Sales!$O$6:$O$265,A5,Sales!$J$6:$J$265)+SUMIF(Sales!$O$6:$O$265,A5,Sales!$K$6:$K$265)+SUMIF(Sales!$O$6:$O$265,A5,Sales!$M$6:$M$265) -> 0 | E5: =C5-D5 -> 0 | F5: =SUMIF(Expenses!$E$5:$E$111,A5,Expenses!$D$5:$D$111) -> 0 | G5: =E5-F5 -> 0 | H5: =IF(C5=0,0,G5/C5) -> 0 | I5: =MAX(0,G5)*Settings!$B$10 -> 0
A6: 2026-03 | B6: =COUNTIF(Sales!$O$6:$O$265,A6) -> 0 | C6: =SUMIF(Sales!$O$6:$O$265,A6,Sales!$H$6:$H$265) -> 0 | D6: =SUMIF(Sales!$O$6:$O$265,A6,Sales!$I$6:$I$265)+SUMIF(Sales!$O$6:$O$265,A6,Sales!$J$6:$J$265)+SUMIF(Sales!$O$6:$O$265,A6,Sales!$K$6:$K$265)+SUMIF(Sales!$O$6:$O$265,A6,Sales!$M$6:$M$265) -> 0 | E6: =C6-D6 -> 0 | F6: =SUMIF(Expenses!$E$5:$E$111,A6,Expenses!$D$5:$D$111) -> 0 | G6: =E6-F6 -> 0 | H6: =IF(C6=0,0,G6/C6) -> 0 | I6: =MAX(0,G6)*Settings!$B$10 -> 0
A7: 2026-04 | B7: =COUNTIF(Sales!$O$6:$O$265,A7) -> 0 | C7: =SUMIF(Sales!$O$6:$O$265,A7,Sales!$H$6:$H$265) -> 0 | D7: =SUMIF(Sales!$O$6:$O$265,A7,Sales!$I$6:$I$265)+SUMIF(Sales!$O$6:$O$265,A7,Sales!$J$6:$J$265)+SUMIF(Sales!$O$6:$O$265,A7,Sales!$K$6:$K$265)+SUMIF(Sales!$O$6:$O$265,A7,Sales!$M$6:$M$265) -> 0 | E7: =C7-D7 -> 0 | F7: =SUMIF(Expenses!$E$5:$E$111,A7,Expenses!$D$5:$D$111) -> 0 | G7: =E7-F7 -> 0 | H7: =IF(C7=0,0,G7/C7) -> 0 | I7: =MAX(0,G7)*Settings!$B$10 -> 0
A8: 2026-05 | B8: =COUNTIF(Sales!$O$6:$O$265,A8) -> 0 | C8: =SUMIF(Sales!$O$6:$O$265,A8,Sales!$H$6:$H$265) -> 0 | D8: =SUMIF(Sales!$O$6:$O$265,A8,Sales!$I$6:$I$265)+SUMIF(Sales!$O$6:$O$265,A8,Sales!$J$6:$J$265)+SUMIF(Sales!$O$6:$O$265,A8,Sales!$K$6:$K$265)+SUMIF(Sales!$O$6:$O$265,A8,Sales!$M$6:$M$265) -> 0 | E8: =C8-D8 -> 0 | F8: =SUMIF(Expenses!$E$5:$E$111,A8,Expenses!$D$5:$D$111) -> 0 | G8: =E8-F8 -> 0 | H8: =IF(C8=0,0,G8/C8) -> 0 | I8: =MAX(0,G8)*Settings!$B$10 -> 0
A9: 2026-06 | B9: =COUNTIF(Sales!$O$6:$O$265,A9) -> 0 | C9: =SUMIF(Sales!$O$6:$O$265,A9,Sales!$H$6:$H$265) -> 0 | D9: =SUMIF(Sales!$O$6:$O$265,A9,Sales!$I$6:$I$265)+SUMIF(Sales!$O$6:$O$265,A9,Sales!$J$6:$J$265)+SUMIF(Sales!$O$6:$O$265,A9,Sales!$K$6:$K$265)+SUMIF(Sales!$O$6:$O$265,A9,Sales!$M$6:$M$265) -> 0 | E9: =C9-D9 -> 0 | F9: =SUMIF(Expenses!$E$5:$E$111,A9,Expenses!$D$5:$D$111) -> 0 | G9: =E9-F9 -> 0 | H9: =IF(C9=0,0,G9/C9) -> 0 | I9: =MAX(0,G9)*Settings!$B$10 -> 0
A10: 2026-07 | B10: =COUNTIF(Sales!$O$6:$O$265,A10) -> 31 | C10: =SUMIF(Sales!$O$6:$O$265,A10,Sales!$H$6:$H$265) -> 264 | D10: =SUMIF(Sales!$O$6:$O$265,A10,Sales!$I$6:$I$265)+SUMIF(Sales!$O$6:$O$265,A10,Sales!$J$6:$J$265)+SUMIF(Sales!$O$6:$O$265,A10,Sales!$K$6:$K$265)+SUMIF(Sales!$O$6:$O$265,A10,Sales!$M$6:$M$265) -> 44.5344 | E10: =C10-D10 -> 219.4656 | F10: =SUMIF(Expenses!$E$5:$E$111,A10,Expenses!$D$5:$D$111) -> 60 | G10: =E10-F10 -> 159.4656 | H10: =IF(C10=0,0,G10/C10) -> 0.60403636 | I10: =MAX(0,G10)*Settings!$B$10 -> 39.8664
A11: 2026-08 | B11: =COUNTIF(Sales!$O$6:$O$265,A11) -> 29 | C11: =SUMIF(Sales!$O$6:$O$265,A11,Sales!$H$6:$H$265) -> 249 | D11: =SUMIF(Sales!$O$6:$O$265,A11,Sales!$I$6:$I$265)+SUMIF(Sales!$O$6:$O$265,A11,Sales!$J$6:$J$265)+SUMIF(Sales!$O$6:$O$265,A11,Sales!$K$6:$K$265)+SUMIF(Sales!$O$6:$O$265,A11,Sales!$M$6:$M$265) -> 39.6279 | E11: =C11-D11 -> 209.3721 | F11: =SUMIF(Expenses!$E$5:$E$111,A11,Expenses!$D$5:$D$111) -> 95 | G11: =E11-F11 -> 114.3721 | H11: =IF(C11=0,0,G11/C11) -> 0.4593257 | I11: =MAX(0,G11)*Settings!$B$10 -> 28.593025
A12: 2026-09 | B12: =COUNTIF(Sales!$O$6:$O$265,A12) -> 0 | C12: =SUMIF(Sales!$O$6:$O$265,A12,Sales!$H$6:$H$265) -> 0 | D12: =SUMIF(Sales!$O$6:$O$265,A12,Sales!$I$6:$I$265)+SUMIF(Sales!$O$6:$O$265,A12,Sales!$J$6:$J$265)+SUMIF(Sales!$O$6:$O$265,A12,Sales!$K$6:$K$265)+SUMIF(Sales!$O$6:$O$265,A12,Sales!$M$6:$M$265) -> 0 | E12: =C12-D12 -> 0 | F12: =SUMIF(Expenses!$E$5:$E$111,A12,Expenses!$D$5:$D$111) -> 75 | G12: =E12-F12 -> -75 | H12: =IF(C12=0,0,G12/C12) -> 0 | I12: =MAX(0,G12)*Settings!$B$10 -> 0
A13: 2026-10 | B13: =COUNTIF(Sales!$O$6:$O$265,A13) -> 0 | C13: =SUMIF(Sales!$O$6:$O$265,A13,Sales!$H$6:$H$265) -> 0 | D13: =SUMIF(Sales!$O$6:$O$265,A13,Sales!$I$6:$I$265)+SUMIF(Sales!$O$6:$O$265,A13,Sales!$J$6:$J$265)+SUMIF(Sales!$O$6:$O$265,A13,Sales!$K$6:$K$265)+SUMIF(Sales!$O$6:$O$265,A13,Sales!$M$6:$M$265) -> 0 | E13: =C13-D13 -> 0 | F13: =SUMIF(Expenses!$E$5:$E$111,A13,Expenses!$D$5:$D$111) -> 0 | G13: =E13-F13 -> 0 | H13: =IF(C13=0,0,G13/C13) -> 0 | I13: =MAX(0,G13)*Settings!$B$10 -> 0
A14: 2026-11 | B14: =COUNTIF(Sales!$O$6:$O$265,A14) -> 0 | C14: =SUMIF(Sales!$O$6:$O$265,A14,Sales!$H$6:$H$265) -> 0 | D14: =SUMIF(Sales!$O$6:$O$265,A14,Sales!$I$6:$I$265)+SUMIF(Sales!$O$6:$O$265,A14,Sales!$J$6:$J$265)+SUMIF(Sales!$O$6:$O$265,A14,Sales!$K$6:$K$265)+SUMIF(Sales!$O$6:$O$265,A14,Sales!$M$6:$M$265) -> 0 | E14: =C14-D14 -> 0 | F14: =SUMIF(Expenses!$E$5:$E$111,A14,Expenses!$D$5:$D$111) -> 0 | G14: =E14-F14 -> 0 | H14: =IF(C14=0,0,G14/C14) -> 0 | I14: =MAX(0,G14)*Settings!$B$10 -> 0
A15: 2026-12 | B15: =COUNTIF(Sales!$O$6:$O$265,A15) -> 0 | C15: =SUMIF(Sales!$O$6:$O$265,A15,Sales!$H$6:$H$265) -> 0 | D15: =SUMIF(Sales!$O$6:$O$265,A15,Sales!$I$6:$I$265)+SUMIF(Sales!$O$6:$O$265,A15,Sales!$J$6:$J$265)+SUMIF(Sales!$O$6:$O$265,A15,Sales!$K$6:$K$265)+SUMIF(Sales!$O$6:$O$265,A15,Sales!$M$6:$M$265) -> 0 | E15: =C15-D15 -> 0 | F15: =SUMIF(Expenses!$E$5:$E$111,A15,Expenses!$D$5:$D$111) -> 0 | G15: =E15-F15 -> 0 | H15: =IF(C15=0,0,G15/C15) -> 0 | I15: =MAX(0,G15)*Settings!$B$10 -> 0
A16: YEAR | B16: =SUM(B4:B15) -> 60 | C16: =SUM(C4:C15) -> 513 | D16: =SUM(D4:D15) -> 84.1623 | E16: =SUM(E4:E15) -> 428.8377 | F16: =SUM(F4:F15) -> 230 | G16: =SUM(G4:G15) -> 198.8377 | H16: =IF(C16=0,0,G16/C16) -> 0.38759786 | I16: =SUM(I4:I15) -> 68.459425
A18: Sales tax collected by Etsy and remitted on your behalf is excluded from gross. The blank rows use empty-string guards so pasting more orders below works without edits.

Sheet Settings
A1: Settings
A2: Fee rates and assumptions.
A4: How to use: type your numbers in the yellow cells (blue text). Everything else calculates.
A5: Transaction fee % | B5: 0.065
A6: Payment processing % | B6: 0.03
A7: Payment processing fixed $ | B7: 0.25
A8: Listing fee $ | B8: 0.2
A9: Offsite ads fee % (if applicable) | B9: 0.15
A10: Estimated income tax rate (for set-aside) | B10: 0.25

Sheet Sales
A1: Sales
A2: One row per order.
A4: How to use: type your numbers in the yellow cells (blue text). Everything else calculates.
A5: Date | B5: Order # | C5: Item | D5: Qty | E5: Item price | F5: Shipping charged | G5: Sales tax collected | H5: Gross | I5: Transaction fee | J5: Processing fee | K5: Listing fee | L5: Offsite ad? (Y) | M5: Ad fee | N5: Net payout | O5: Month
A6: 2026-07-03 | B6: 321000 | C6: Wedding budget spreadsheet | D6: 1 | E6: 12 | F6: 0 | G6: 0.84 | H6: =D6*E6+F6 -> 12 | I6: =H6*Settings!$B$5 -> 0.78 | J6: =(H6+G6)*Settings!$B$6+Settings!$B$7 -> 0.6352 | K6: =Settings!$B$8*D6 -> 0.2 | M6: =IF(L6="Y",H6*Settings!$B$9,0) -> 0 | N6: =H6-I6-J6-K6-M6 -> 10.3848 | O6: =IF(A6="","",LEFT(A6,7)) -> 2026-07
A7: 2026-07-04 | B7: 321001 | C7: Monthly budget planner | D7: 1 | E7: 9 | F7: 0 | G7: 0.63 | H7: =D7*E7+F7 -> 9 | I7: =H7*Settings!$B$5 -> 0.585 | J7: =(H7+G7)*Settings!$B$6+Settings!$B$7 -> 0.5389 | K7: =Settings!$B$8*D7 -> 0.2 | L7: Y | M7: =IF(L7="Y",H7*Settings!$B$9,0) -> 1.35 | N7: =H7-I7-J7-K7-M7 -> 6.3261 | O7: =IF(A7="","",LEFT(A7,7)) -> 2026-07
A8: 2026-07-05 | B8: 321002 | C8: Debt payoff tracker | D8: 1 | E8: 8 | F8: 0 | G8: 0.56 | H8: =D8*E8+F8 -> 8 | I8: =H8*Settings!$B$5 -> 0.52 | J8: =(H8+G8)*Settings!$B$6+Settings!$B$7 -> 0.5068 | K8: =Settings!$B$8*D8 -> 0.2 | M8: =IF(L8="Y",H8*Settings!$B$9,0) -> 0 | N8: =H8-I8-J8-K8-M8 -> 6.7732 | O8: =IF(A8="","",LEFT(A8,7)) -> 2026-07
A9: 2026-07-06 | B9: 321003 | C9: Bill tracker | D9: 1 | E9: 7 | F9: 0 | G9: 0.49 | H9: =D9*E9+F9 -> 7 | I9: =H9*Settings!$B$5 -> 0.455 | J9: =(H9+G9)*Settings!$B$6+Settings!$B$7 -> 0.4747 | K9: =Settings!$B$8*D9 -> 0.2 | M9: =IF(L9="Y",H9*Settings!$B$9,0) -> 0 | N9: =H9-I9-J9-K9-M9 -> 5.8703 | O9: =IF(A9="","",LEFT(A9,7)) -> 2026-07
A10: 2026-07-07 | B10: 321004 | C10: Debt payoff tracker | D10: 1 | E10: 8 | F10: 0 | G10: 0.56 | H10: =D10*E10+F10 -> 8 | I10: =H10*Settings!$B$5 -> 0.52 | J10: =(H10+G10)*Settings!$B$6+Settings!$B$7 -> 0.5068 | K10: =Settings!$B$8*D10 -> 0.2 | M10: =IF(L10="Y",H10*Settings!$B$9,0) -> 0 | N10: =H10-I10-J10-K10-M10 -> 6.7732 | O10: =IF(A10="","",LEFT(A10,7)) -> 2026-07
A11: 2026-07-09 | B11: 321005 | C11: Bill tracker | D11: 1 | E11: 7 | F11: 0 | G11: 0.49 | H11: =D11*E11+F11 -> 7 | I11: =H11*Settings!$B$5 -> 0.455 | J11: =(H11+G11)*Settings!$B$6+Settings!$B$7 -> 0.4747 | K11: =Settings!$B$8*D11 -> 0.2 | M11: =IF(L11="Y",H11*Settings!$B$9,0) -> 0 | N11: =H11-I11-J11-K11-M11 -> 5.8703 | O11: =IF(A11="","",LEFT(A11,7)) -> 2026-07
A12: 2026-07-09 | B12: 321006 | C12: Debt payoff tracker | D12: 1 | E12: 8 | F12: 0 | G12: 0.56 | H12: =D12*E12+F12 -> 8 | I12: =H12*Settings!$B$5 -> 0.52 | J12: =(H12+G12)*Settings!$B$6+Settings!$B$7 -> 0.5068 | K12: =Settings!$B$8*D12 -> 0.2 | M12: =IF(L12="Y",H12*Settings!$B$9,0) -> 0 | N12: =H12-I12-J12-K12-M12 -> 6.7732 | O12: =IF(A12="","",LEFT(A12,7)) -> 2026-07
A13: 2026-07-09 | B13: 321007 | C13: Debt payoff tracker | D13: 1 | E13: 8 | F13: 0 | G13: 0.56 | H13: =D13*E13+F13 -> 8 | I13: =H13*Settings!$B$5 -> 0.52 | J13: =(H13+G13)*Settings!$B$6+Settings!$B$7 -> 0.5068 | K13: =Settings!$B$8*D13 -> 0.2 | M13: =IF(L13="Y",H13*Settings!$B$9,0) -> 0 | N13: =H13-I13-J13-K13-M13 -> 6.7732 | O13: =IF(A13="","",LEFT(A13,7)) -> 2026-07
A14: 2026-07-10 | B14: 321008 | C14: Savings goals tracker | D14: 1 | E14: 8 | F14: 0 | G14: 0.56 | H14: =D14*E14+F14 -> 8 | I14: =H14*Settings!$B$5 -> 0.52 | J14: =(H14+G14)*Settings!$B$6+Settings!$B$7 -> 0.5068 | K14: =Settings!$B$8*D14 -> 0.2 | L14: Y | M14: =IF(L14="Y",H14*Settings!$B$9,0) -> 1.2 | N14: =H14-I14-J14-K14-M14 -> 5.5732 | O14: =IF(A14="","",LEFT(A14,7)) -> 2026-07
A15: 2026-07-10 | B15: 321009 | C15: Bill tracker | D15: 1 | E15: 7 | F15: 0 | G15: 0.49 | H15: =D15*E15+F15 -> 7 | I15: =H15*Settings!$B$5 -> 0.455 | J15: =(H15+G15)*Settings!$B$6+Settings!$B$7 -> 0.4747 | K15: =Settings!$B$8*D15 -> 0.2 | M15: =IF(L15="Y",H15*Settings!$B$9,0) -> 0 | N15: =H15-I15-J15-K15-M15 -> 5.8703 | O15: =IF(A15="","",LEFT(A15,7)) -> 2026-07
A16: 2026-07-10 | B16: 321010 | C16: Debt payoff tracker | D16: 1 | E16: 8 | F16: 0 | G16: 0.56 | H16: =D16*E16+F16 -> 8 | I16: =H16*Settings!$B$5 -> 0.52 | J16: =(H16+G16)*Settings!$B$6+Settings!$B$7 -> 0.5068 | K16: =Settings!$B$8*D16 -> 0.2 | M16: =IF(L16="Y",H16*Settings!$B$9,0) -> 0 | N16: =H16-I16-J16-K16-M16 -> 6.7732 | O16: =IF(A16="","",LEFT(A16,7)) -> 2026-07
A17: 2026-07-10 | B17: 321011 | C17: Wedding budget spreadsheet | D17: 1 | E17: 12 | F17: 0 | G17: 0.84 | H17: =D17*E17+F17 -> 12 | I17: =H17*Settings!$B$5 -> 0.78 | J17: =(H17+G17)*Settings!$B$6+Settings!$B$7 -> 0.6352 | K17: =Settings!$B$8*D17 -> 0.2 | M17: =IF(L17="Y",H17*Settings!$B$9,0) -> 0 | N17: =H17-I17-J17-K17-M17 -> 10.3848 | O17: =IF(A17="","",LEFT(A17,7)) -> 2026-07
A18: 2026-07-10 | B18: 321012 | C18: Bill tracker | D18: 1 | E18: 7 | F18: 0 | G18: 0.49 | H18: =D18*E18+F18 -> 7 | I18: =H18*Settings!$B$5 -> 0.455 | J18: =(H18+G18)*Settings!$B$6+Settings!$B$7 -> 0.4747 | K18: =Settings!$B$8*D18 -> 0.2 | L18: Y | M18: =IF(L18="Y",H18*Settings!$B$9,0) -> 1.05 | N18: =H18-I18-J18-K18-M18 -> 4.8203 | O18: =IF(A18="","",LEFT(A18,7)) -> 2026-07
A19: 2026-07-12 | B19: 321013 | C19: Debt payoff tracker | D19: 1 | E19: 8 | F19: 0 | G19: 0.56 | H19: =D19*E19+F19 -> 8 | I19: =H19*Settings!$B$5 -> 0.52 | J19: =(H19+G19)*Settings!$B$6+Settings!$B$7 -> 0.5068 | K19: =Settings!$B$8*D19 -> 0.2 | M19: =IF(L19="Y",H19*Settings!$B$9,0) -> 0 | N19: =H19-I19-J19-K19-M19 -> 6.7732 | O19: =IF(A19="","",LEFT(A19,7)) -> 2026-07
A20: 2026-07-14 | B20: 321014 | C20: Monthly budget planner | D20: 1 | E20: 9 | F20: 0 | G20: 0.63 | H20: =D20*E20+F20 -> 9 | I20: =H20*Settings!$B$5 -> 0.585 | J20: =(H20+G20)*Settings!$B$6+Settings!$B$7 -> 0.5389 | K20: =Settings!$B$8*D20 -> 0.2 | M20: =IF(L20="Y",H20*Settings!$B$9,0) -> 0 | N20: =H20-I20-J20-K20-M20 -> 7.6761 | O20: =IF(A20="","",LEFT(A20,7)) -> 2026-07
A21: 2026-07-15 | B21: 321015 | C21: Debt payoff tracker | D21: 1 | E21: 8 | F21: 0 | G21: 0.56 | H21: =D21*E21+F21 -> 8 | I21: =H21*Settings!$B$5 -> 0.52 | J21: =(H21+G21)*Settings!$B$6+Settings!$B$7 -> 0.5068 | K21: =Settings!$B$8*D21 -> 0.2 | M21: =IF(L21="Y",H21*Settings!$B$9,0) -> 0 | N21: =H21-I21-J21-K21-M21 -> 6.7732 | O21: =IF(A21="","",LEFT(A21,7)) -> 2026-07
A22: 2026-07-15 | B22: 321016 | C22: Bill tracker | D22: 1 | E22: 7 | F22: 0 | G22: 0.49 | H22: =D22*E22+F22 -> 7 | I22: =H22*Settings!$B$5 -> 0.455 | J22: =(H22+G22)*Settings!$B$6+Settings!$B$7 -> 0.4747 | K22: =Settings!$B$8*D22 -> 0.2 | M22: =IF(L22="Y",H22*Settings!$B$9,0) -> 0 | N22: =H22-I22-J22-K22-M22 -> 5.8703 | O22: =IF(A22="","",LEFT(A22,7)) -> 2026-07
A23: 2026-07-15 | B23: 321017 | C23: Monthly budget planner | D23: 1 | E23: 9 | F23: 0 | G23: 0.63 | H23: =D23*E23+F23 -> 9 | I23: =H23*Settings!$B$5 -> 0.585 | J23: =(H23+G23)*Settings!$B$6+Settings!$B$7 -> 0.5389 | K23: =Settings!$B$8*D23 -> 0.2 | M23: =IF(L23="Y",H23*Settings!$B$9,0) -> 0 | N23: =H23-I23-J23-K23-M23 -> 7.6761 | O23: =IF(A23="","",LEFT(A23,7)) -> 2026-07
A24: 2026-07-16 | B24: 321018 | C24: Savings goals tracker | D24: 1 | E24: 8 | F24: 0 | G24: 0.56 | H24: =D24*E24+F24 -> 8 | I24: =H24*Settings!$B$5 -> 0.52 | J24: =(H24+G24)*Settings!$B$6+Settings!$B$7 -> 0.5068 | K24: =Settings!$B$8*D24 -> 0.2 | M24: =IF(L24="Y",H24*Settings!$B$9,0) -> 0 | N24: =H24-I24-J24-K24-M24 -> 6.7732 | O24: =IF(A24="","",LEFT(A24,7)) -> 2026-07
A25: 2026-07-18 | B25: 321019 | C25: Savings goals tracker | D25: 1 | E25: 8 | F25: 0 | G25: 0.56 | H25: =D25*E25+F25 -> 8 | I25: =H25*Settings!$B$5 -> 0.52 | J25: =(H25+G25)*Settings!$B$6+Settings!$B$7 -> 0.5068 | K25: =Settings!$B$8*D25 -> 0.2 | M25: =IF(L25="Y",H25*Settings!$B$9,0) -> 0 | N25: =H25-I25-J25-K25-M25 -> 6.7732 | O25: =IF(A25="","",LEFT(A25,7)) -> 2026-07
A26: 2026-07-18 | B26: 321020 | C26: Bill tracker | D26: 1 | E26: 7 | F26: 0 | G26: 0.49 | H26: =D26*E26+F26 -> 7 | I26: =H26*Settings!$B$5 -> 0.455 | J26: =(H26+G26)*Settings!$B$6+Settings!$B$7 -> 0.4747 | K26: =Settings!$B$8*D26 -> 0.2 | M26: =IF(L26="Y",H26*Settings!$B$9,0) -> 0 | N26: =H26-I26-J26-K26-M26 -> 5.8703 | O26: =IF(A26="","",LEFT(A26,7)) -> 2026-07
A27: 2026-07-20 | B27: 321021 | C27: Monthly budget planner | D27: 1 | E27: 9 | F27: 0 | G27: 0.63 | H27: =D27*E27+F27 -> 9 | I27: =H27*Settings!$B$5 -> 0.585 | J27: =(H27+G27)*Settings!$B$6+Settings!$B$7 -> 0.5389 | K27: =Settings!$B$8*D27 -> 0.2 | L27: Y | M27: =IF(L27="Y",H27*Settings!$B$9,0) -> 1.35 | N27: =H27-I27-J27-K27-M27 -> 6.3261 | O27: =IF(A27="","",LEFT(A27,7)) -> 2026-07
A28: 2026-07-22 | B28: 321022 | C28: Bill tracker | D28: 1 | E28: 7 | F28: 0 | G28: 0.49 | H28: =D28*E28+F28 -> 7 | I28: =H28*Settings!$B$5 -> 0.455 | J28: =(H28+G28)*Settings!$B$6+Settings!$B$7 -> 0.4747 | K28: =Settings!$B$8*D28 -> 0.2 | M28: =IF(L28="Y",H28*Settings!$B$9,0) -> 0 | N28: =H28-I28-J28-K28-M28 -> 5.8703 | O28: =IF(A28="","",LEFT(A28,7)) -> 2026-07
A29: 2026-07-23 | B29: 321023 | C29: Monthly budget planner | D29: 1 | E29: 9 | F29: 0 | G29: 0.63 | H29: =D29*E29+F29 -> 9 | I29: =H29*Settings!$B$5 -> 0.585 | J29: =(H29+G29)*Settings!$B$6+Settings!$B$7 -> 0.5389 | K29: =Settings!$B$8*D29 -> 0.2 | M29: =IF(L29="Y",H29*Settings!$B$9,0) -> 0 | N29: =H29-I29-J29-K29-M29 -> 7.6761 | O29: =IF(A29="","",LEFT(A29,7)) -> 2026-07
A30: 2026-07-23 | B30: 321024 | C30: Bill tracker | D30: 1 | E30: 7 | F30: 0 | G30: 0.49 | H30: =D30*E30+F30 -> 7 | I30: =H30*Settings!$B$5 -> 0.455 | J30: =(H30+G30)*Settings!$B$6+Settings!$B$7 -> 0.4747 | K30: =Settings!$B$8*D30 -> 0.2 | M30: =IF(L30="Y",H30*Settings!$B$9,0) -> 0 | N30: =H30-I30-J30-K30-M30 -> 5.8703 | O30: =IF(A30="","",LEFT(A30,7)) -> 2026-07
A31: 2026-07-25 | B31: 321025 | C31: Savings goals tracker | D31: 1 | E31: 8 | F31: 0 | G31: 0.56 | H31: =D31*E31+F31 -> 8 | I31: =H31*Settings!$B$5 -> 0.52 | J31: =(H31+G31)*Settings!$B$6+Settings!$B$7 -> 0.5068 | K31: =Settings!$B$8*D31 -> 0.2 | M31: =IF(L31="Y",H31*Settings!$B$9,0) -> 0 | N31: =H31-I31-J31-K31-M31 -> 6.7732 | O31: =IF(A31="","",LEFT(A31,7)) -> 2026-07
A32: 2026-07-26 | B32: 321026 | C32: Bill tracker | D32: 1 | E32: 7 | F32: 0 | G32: 0.49 | H32: =D32*E32+F32 -> 7 | I32: =H32*Settings!$B$5 -> 0.455 | J32: =(H32+G32)*Settings!$B$6+Settings!$B$7 -> 0.4747 | K32: =Settings!$B$8*D32 -> 0.2 | M32: =IF(L32="Y",H32*Settings!$B$9,0) -> 0 | N32: =H32-I32-J32-K32-M32 -> 5.8703 | O32: =IF(A32="","",LEFT(A32,7)) -> 2026-07
A33: 2026-07-26 | B33: 321027 | C33: Wedding budget spreadsheet | D33: 1 | E33: 12 | F33: 0 | G33: 0.84 | H33: =D33*E33+F33 -> 12 | I33: =H33*Settings!$B$5 -> 0.78 | J33: =(H33+G33)*Settings!$B$6+Settings!$B$7 -> 0.6352 | K33: =Settings!$B$8*D33 -> 0.2 | M33: =IF(L33="Y",H33*Settings!$B$9,0) -> 0 | N33: =H33-I33-J33-K33-M33 -> 10.3848 | O33: =IF(A33="","",LEFT(A33,7)) -> 2026-07
A34: 2026-07-28 | B34: 321028 | C34: Wedding budget spreadsheet | D34: 1 | E34: 12 | F34: 0 | G34: 0.84 | H34: =D34*E34+F34 -> 12 | I34: =H34*Settings!$B$5 -> 0.78 | J34: =(H34+G34)*Settings!$B$6+Settings!$B$7 -> 0.6352 | K34: =Settings!$B$8*D34 -> 0.2 | M34: =IF(L34="Y",H34*Settings!$B$9,0) -> 0 | N34: =H34-I34-J34-K34-M34 -> 10.3848 | O34: =IF(A34="","",LEFT(A34,7)) -> 2026-07
A35: 2026-07-29 | B35: 321029 | C35: Wedding budget spreadsheet | D35: 1 | E35: 12 | F35: 0 | G35: 0.84 | H35: =D35*E35+F35 -> 12 | I35: =H35*Settings!$B$5 -> 0.78 | J35: =(H35+G35)*Settings!$B$6+Settings!$B$7 -> 0.6352 | K35: =Settings!$B$8*D35 -> 0.2 | M35: =IF(L35="Y",H35*Settings!$B$9,0) -> 0 | N35: =H35-I35-J35-K35-M35 -> 10.3848 | O35: =IF(A35="","",LEFT(A35,7)) -> 2026-07
A36: 2026-07-31 | B36: 321030 | C36: Debt payoff tracker | D36: 1 | E36: 8 | F36: 0 | G36: 0.56 | H36: =D36*E36+F36 -> 8 | I36: =H36*Settings!$B$5 -> 0.52 | J36: =(H36+G36)*Settings!$B$6+Settings!$B$7 -> 0.5068 | K36: =Settings!$B$8*D36 -> 0.2 | M36: =IF(L36="Y",H36*Settings!$B$9,0) -> 0 | N36: =H36-I36-J36-K36-M36 -> 6.7732 | O36: =IF(A36="","",LEFT(A36,7)) -> 2026-07
A37: 2026-08-02 | B37: 321031 | C37: Wedding budget spreadsheet | D37: 1 | E37: 12 | F37: 0 | G37: 0.84 | H37: =D37*E37+F37 -> 12 | I37: =H37*Settings!$B$5 -> 0.78 | J37: =(H37+G37)*Settings!$B$6+Settings!$B$7 -> 0.6352 | K37: =Settings!$B$8*D37 -> 0.2 | M37: =IF(L37="Y",H37*Settings!$B$9,0) -> 0 | N37: =H37-I37-J37-K37-M37 -> 10.3848 | O37: =IF(A37="","",LEFT(A37,7)) -> 2026-08
A38: 2026-08-02 | B38: 321032 | C38: Wedding budget spreadsheet | D38: 1 | E38: 12 | F38: 0 | G38: 0.84 | H38: =D38*E38+F38 -> 12 | I38: =H38*Settings!$B$5 -> 0.78 | J38: =(H38+G38)*Settings!$B$6+Settings!$B$7 -> 0.6352 | K38: =Settings!$B$8*D38 -> 0.2 | M38: =IF(L38="Y",H38*Settings!$B$9,0) -> 0 | N38: =H38-I38-J38-K38-M38 -> 10.3848 | O38: =IF(A38="","",LEFT(A38,7)) -> 2026-08
A39: 2026-08-04 | B39: 321033 | C39: Bill tracker | D39: 1 | E39: 7 | F39: 0 | G39: 0.49 | H39: =D39*E39+F39 -> 7 | I39: =H39*Settings!$B$5 -> 0.455 | J39: =(H39+G39)*Settings!$B$6+Settings!$B$7 -> 0.4747 | K39: =Settings!$B$8*D39 -> 0.2 | M39: =IF(L39="Y",H39*Settings!$B$9,0) -> 0 | N39: =H39-I39-J39-K39-M39 -> 5.8703 | O39: =IF(A39="","",LEFT(A39,7)) -> 2026-08
... A54: 2026-08-21 | B54: 321048 | C54: Wedding budget spreadsheet | D54: 1 | E54: 12 | F54: 0 | G54: 0.84 | H54: =D54*E54+F54 -> 12 | I54: =H54*Settings!$B$5 -> 0.78 | J54: =(H54+G54)*Settings!$B$6+Settings!$B$7 -> 0.6352 | K54: =Settings!$B$8*D54 -> 0.2 | M54: =IF(L54="Y",H54*Settings!$B$9,0) -> 0 | N54: =H54-I54-J54-K54-M54 -> 10.3848 | O54: =IF(A54="","",LEFT(A54,7)) -> 2026-08
A55: 2026-08-23 | B55: 321049 | C55: Bill tracker | D55: 1 | E55: 7 | F55: 0 | G55: 0.49 | H55: =D55*E55+F55 -> 7 | I55: =H55*Settings!$B$5 -> 0.455 | J55: =(H55+G55)*Settings!$B$6+Settings!$B$7 -> 0.4747 | K55: =Settings!$B$8*D55 -> 0.2 | L55: Y | M55: =IF(L55="Y",H55*Settings!$B$9,0) -> 1.05 | N55: =H55-I55-J55-K55-M55 -> 4.8203 | O55: =IF(A55="","",LEFT(A55,7)) -> 2026-08
...

Sheet Expenses
A1: Expenses
A3: How to use: type your numbers in the yellow cells (blue text). Everything else calculates.
A4: Date | B4: Category | C4: Description | D4: Amount | E4: Month
A5: 2026-07-03 | B5: Software | C5: Canva Pro | D5: 15 | E5: =IF(A5="","",LEFT(A5,7)) -> 2026-07
A6: 2026-07-10 | B6: Ads | C6: Etsy Ads | D6: 45 | E6: =IF(A6="","",LEFT(A6,7)) -> 2026-07
A7: 2026-08-03 | B7: Software | C7: Canva Pro | D7: 15 | E7: =IF(A7="","",LEFT(A7,7)) -> 2026-08
A8: 2026-08-10 | B8: Ads | C8: Etsy Ads | D8: 60 | E8: =IF(A8="","",LEFT(A8,7)) -> 2026-08
A9: 2026-08-20 | B9: Tools | C9: Keyword research tool | D9: 20 | E9: =IF(A9="","",LEFT(A9,7)) -> 2026-08
A10: 2026-09-03 | B10: Software | C10: Canva Pro | D10: 15 | E10: =IF(A10="","",LEFT(A10,7)) -> 2026-09
A11: 2026-09-10 | B11: Ads | C11: Etsy Ads | D11: 60 | E11: =IF(A11="","",LEFT(A11,7)) -> 2026-09
E12: =IF(A12="","",LEFT(A12,7))
E13: =IF(A13="","",LEFT(A13,7))
E14: =IF(A14="","",LEFT(A14,7))
E15: =IF(A15="","",LEFT(A15,7))
E16: =IF(A16="","",LEFT(A16,7))
E17: =IF(A17="","",LEFT(A17,7))
E18: =IF(A18="","",LEFT(A18,7))
E19: =IF(A19="","",LEFT(A19,7))
E20: =IF(A20="","",LEFT(A20,7))
E21: =IF(A21="","",LEFT(A21,7))
E22: =IF(A22="","",LEFT(A22,7))
E23: =IF(A23="","",LEFT(A23,7))
... E111: =IF(A111="","",LEFT(A111,7))
